[
  {
    "x": 0,
    "y": 0,
    "z": 0,
    "block": "minecraft:stone"
  },
  {
    "x": 1,
    "y": 0,
    "z": 0,
    "block": "minecraft:stone"
  },
  {
    "x": 2,
    "y": 0,
    "z": 0,
    "block": "minecraft:stone"
  },
  {
    "x": 3,
    "y": 0,
    "z": 0,
    "block": "minecraft:stone"
  },
  {
    "x": 4,
    "y": 0,
    "z": 0,
    "block": "minecraft:stone"
  },
  {
    "x": 5,
    "y": 0,
    "z": 0,
    "block": "minecraft:stone"
  },
  {
    "x": 6,
    "y": 0,
    "z": 0,
    "block": "minecraft:stone"
  },
  {
    "x": 7,
    "y": 0,
    "z": 0,
    "block": "minecraft:stone"
  },
  {
    "x": 8,
    "y": 0,
    "z": 0,
    "block": "minecraft:stone"
  },
  {
    "x": 9,
    "y": 0,
    "z": 0,
    "block": "minecraft:stone"
  },
  {
    "x": 10,
    "y": 0,
    "z": 0,
    "block": "minecraft:stone"
  },
  {
    "x": 11,
    "y": 0,
    "z": 0,
    "block": "minecraft:stone"
  },
  {
    "x": 12,
    "y": 0,
    "z": 0,
    "block": "minecraft:stone"
  },
  {
    "x": 13,
    "y": 0,
    "z": 0,
    "block": "minecraft:stone"
  },
  {
    "x": 14,
    "y": 0,
    "z": 0,
    "block": "minecraft:stone"
  },
  {
    "x": 15,
    "y": 0,
    "z": 0,
    "block": "minecraft:stone"
  },
  {
    "x": 16,
    "y": 0,
    "z": 0,
    "block": "minecraft:stone"
  },
  {
    "x": 0,
    "y": 0,
    "z": 1,
    "block": "minecraft:stone"
  },
  {
    "x": 1,
    "y": 0,
    "z": 1,
    "block": "minecraft:stone"
  },
  {
    "x": 2,
    "y": 0,
    "z": 1,
    "block": "minecraft:stone"
  },
  {
    "x": 3,
    "y": 0,
    "z": 1,
    "block": "minecraft:stone"
  },
  {
    "x": 4,
    "y": 0,
    "z": 1,
    "block": "minecraft:stone"
  },
  {
    "x": 5,
    "y": 0,
    "z": 1,
    "block": "minecraft:stone"
  },
  {
    "x": 6,
    "y": 0,
    "z": 1,
    "block": "minecraft:stone"
  },
  {
    "x": 7,
    "y": 0,
    "z": 1,
    "block": "minecraft:stone"
  },
  {
    "x": 8,
    "y": 0,
    "z": 1,
    "block": "minecraft:stone"
  },
  {
    "x": 9,
    "y": 0,
    "z": 1,
    "block": "minecraft:stone"
  },
  {
    "x": 10,
    "y": 0,
    "z": 1,
    "block": "minecraft:stone"
  },
  {
    "x": 11,
    "y": 0,
    "z": 1,
    "block": "minecraft:stone"
  },
  {
    "x": 12,
    "y": 0,
    "z": 1,
    "block": "minecraft:stone"
  },
  {
    "x": 13,
    "y": 0,
    "z": 1,
    "block": "minecraft:stone"
  },
  {
    "x": 14,
    "y": 0,
    "z": 1,
    "block": "minecraft:stone"
  },
  {
    "x": 15,
    "y": 0,
    "z": 1,
    "block": "minecraft:stone"
  },
  {
    "x": 16,
    "y": 0,
    "z": 1,
    "block": "minecraft:stone"
  },
  {
    "x": 0,
    "y": 0,
    "z": 2,
    "block": "minecraft:stone"
  },
  {
    "x": 1,
    "y": 0,
    "z": 2,
    "block": "minecraft:stone"
  },
  {
    "x": 2,
    "y": 0,
    "z": 2,
    "block": "minecraft:stone"
  },
  {
    "x": 3,
    "y": 0,
    "z": 2,
    "block": "minecraft:stone"
  },
  {
    "x": 4,
    "y": 0,
    "z": 2,
    "block": "minecraft:stone"
  },
  {
    "x": 5,
    "y": 0,
    "z": 2,
    "block": "minecraft:stone"
  },
  {
    "x": 6,
    "y": 0,
    "z": 2,
    "block": "minecraft:stone"
  },
  {
    "x": 7,
    "y": 0,
    "z": 2,
    "block": "minecraft:stone"
  },
  {
    "x": 8,
    "y": 0,
    "z": 2,
    "block": "minecraft:stone"
  },
  {
    "x": 9,
    "y": 0,
    "z": 2,
    "block": "minecraft:stone"
  },
  {
    "x": 10,
    "y": 0,
    "z": 2,
    "block": "minecraft:stone"
  },
  {
    "x": 11,
    "y": 0,
    "z": 2,
    "block": "minecraft:stone"
  },
  {
    "x": 12,
    "y": 0,
    "z": 2,
    "block": "minecraft:stone"
  },
  {
    "x": 13,
    "y": 0,
    "z": 2,
    "block": "minecraft:stone"
  },
  {
    "x": 14,
    "y": 0,
    "z": 2,
    "block": "minecraft:stone"
  },
  {
    "x": 15,
    "y": 0,
    "z": 2,
    "block": "minecraft:stone"
  },
  {
    "x": 16,
    "y": 0,
    "z": 2,
    "block": "minecraft:stone"
  },
  {
    "x": 0,
    "y": 0,
    "z": 3,
    "block": "minecraft:stone"
  },
  {
    "x": 1,
    "y": 0,
    "z": 3,
    "block": "minecraft:stone"
  },
  {
    "x": 2,
    "y": 0,
    "z": 3,
    "block": "minecraft:stone"
  },
  {
    "x": 3,
    "y": 0,
    "z": 3,
    "block": "minecraft:stone"
  },
  {
    "x": 4,
    "y": 0,
    "z": 3,
    "block": "minecraft:stone"
  },
  {
    "x": 5,
    "y": 0,
    "z": 3,
    "block": "minecraft:stone"
  },
  {
    "x": 6,
    "y": 0,
    "z": 3,
    "block": "minecraft:stone"
  },
  {
    "x": 7,
    "y": 0,
    "z": 3,
    "block": "minecraft:stone"
  },
  {
    "x": 8,
    "y": 0,
    "z": 3,
    "block": "minecraft:stone"
  },
  {
    "x": 9,
    "y": 0,
    "z": 3,
    "block": "minecraft:stone"
  },
  {
    "x": 10,
    "y": 0,
    "z": 3,
    "block": "minecraft:stone"
  },
  {
    "x": 11,
    "y": 0,
    "z": 3,
    "block": "minecraft:stone"
  },
  {
    "x": 12,
    "y": 0,
    "z": 3,
    "block": "minecraft:stone"
  },
  {
    "x": 13,
    "y": 0,
    "z": 3,
    "block": "minecraft:stone"
  },
  {
    "x": 14,
    "y": 0,
    "z": 3,
    "block": "minecraft:stone"
  },
  {
    "x": 15,
    "y": 0,
    "z": 3,
    "block": "minecraft:stone"
  },
  {
    "x": 16,
    "y": 0,
    "z": 3,
    "block": "minecraft:stone"
  },
  {
    "x": 0,
    "y": 0,
    "z": 4,
    "block": "minecraft:stone"
  },
  {
    "x": 1,
    "y": 0,
    "z": 4,
    "block": "minecraft:stone"
  },
  {
    "x": 2,
    "y": 0,
    "z": 4,
    "block": "minecraft:stone"
  },
  {
    "x": 3,
    "y": 0,
    "z": 4,
    "block": "minecraft:stone"
  },
  {
    "x": 4,
    "y": 0,
    "z": 4,
    "block": "minecraft:stone"
  },
  {
    "x": 5,
    "y": 0,
    "z": 4,
    "block": "minecraft:stone"
  },
  {
    "x": 6,
    "y": 0,
    "z": 4,
    "block": "minecraft:stone"
  },
  {
    "x": 7,
    "y": 0,
    "z": 4,
    "block": "minecraft:stone"
  },
  {
    "x": 8,
    "y": 0,
    "z": 4,
    "block": "minecraft:stone"
  },
  {
    "x": 9,
    "y": 0,
    "z": 4,
    "block": "minecraft:stone"
  },
  {
    "x": 10,
    "y": 0,
    "z": 4,
    "block": "minecraft:stone"
  },
  {
    "x": 11,
    "y": 0,
    "z": 4,
    "block": "minecraft:stone"
  },
  {
    "x": 12,
    "y": 0,
    "z": 4,
    "block": "minecraft:stone"
  },
  {
    "x": 13,
    "y": 0,
    "z": 4,
    "block": "minecraft:stone"
  },
  {
    "x": 14,
    "y": 0,
    "z": 4,
    "block": "minecraft:stone"
  },
  {
    "x": 15,
    "y": 0,
    "z": 4,
    "block": "minecraft:stone"
  },
  {
    "x": 16,
    "y": 0,
    "z": 4,
    "block": "minecraft:stone"
  },
  {
    "x": 0,
    "y": 0,
    "z": 5,
    "block": "minecraft:stone"
  },
  {
    "x": 1,
    "y": 0,
    "z": 5,
    "block": "minecraft:stone"
  },
  {
    "x": 2,
    "y": 0,
    "z": 5,
    "block": "minecraft:stone"
  },
  {
    "x": 3,
    "y": 0,
    "z": 5,
    "block": "minecraft:stone"
  },
  {
    "x": 4,
    "y": 0,
    "z": 5,
    "block": "minecraft:stone"
  },
  {
    "x": 5,
    "y": 0,
    "z": 5,
    "block": "minecraft:stone"
  },
  {
    "x": 6,
    "y": 0,
    "z": 5,
    "block": "minecraft:stone"
  },
  {
    "x": 7,
    "y": 0,
    "z": 5,
    "block": "minecraft:stone"
  },
  {
    "x": 8,
    "y": 0,
    "z": 5,
    "block": "minecraft:stone"
  },
  {
    "x": 9,
    "y": 0,
    "z": 5,
    "block": "minecraft:stone"
  },
  {
    "x": 10,
    "y": 0,
    "z": 5,
    "block": "minecraft:stone"
  },
  {
    "x": 11,
    "y": 0,
    "z": 5,
    "block": "minecraft:stone"
  },
  {
    "x": 12,
    "y": 0,
    "z": 5,
    "block": "minecraft:stone"
  },
  {
    "x": 13,
    "y": 0,
    "z": 5,
    "block": "minecraft:stone"
  },
  {
    "x": 14,
    "y": 0,
    "z": 5,
    "block": "minecraft:stone"
  },
  {
    "x": 15,
    "y": 0,
    "z": 5,
    "block": "minecraft:stone"
  },
  {
    "x": 16,
    "y": 0,
    "z": 5,
    "block": "minecraft:stone"
  },
  {
    "x": 0,
    "y": 0,
    "z": 6,
    "block": "minecraft:stone"
  },
  {
    "x": 1,
    "y": 0,
    "z": 6,
    "block": "minecraft:stone"
  },
  {
    "x": 2,
    "y": 0,
    "z": 6,
    "block": "minecraft:stone"
  },
  {
    "x": 3,
    "y": 0,
    "z": 6,
    "block": "minecraft:stone"
  },
  {
    "x": 4,
    "y": 0,
    "z": 6,
    "block": "minecraft:stone"
  },
  {
    "x": 5,
    "y": 0,
    "z": 6,
    "block": "minecraft:stone"
  },
  {
    "x": 6,
    "y": 0,
    "z": 6,
    "block": "minecraft:stone"
  },
  {
    "x": 7,
    "y": 0,
    "z": 6,
    "block": "minecraft:stone"
  },
  {
    "x": 8,
    "y": 0,
    "z": 6,
    "block": "minecraft:stone"
  },
  {
    "x": 9,
    "y": 0,
    "z": 6,
    "block": "minecraft:stone"
  },
  {
    "x": 10,
    "y": 0,
    "z": 6,
    "block": "minecraft:stone"
  },
  {
    "x": 11,
    "y": 0,
    "z": 6,
    "block": "minecraft:stone"
  },
  {
    "x": 12,
    "y": 0,
    "z": 6,
    "block": "minecraft:stone"
  },
  {
    "x": 13,
    "y": 0,
    "z": 6,
    "block": "minecraft:stone"
  },
  {
    "x": 14,
    "y": 0,
    "z": 6,
    "block": "minecraft:stone"
  },
  {
    "x": 15,
    "y": 0,
    "z": 6,
    "block": "minecraft:stone"
  },
  {
    "x": 16,
    "y": 0,
    "z": 6,
    "block": "minecraft:stone"
  },
  {
    "x": 0,
    "y": 0,
    "z": 7,
    "block": "minecraft:stone"
  },
  {
    "x": 1,
    "y": 0,
    "z": 7,
    "block": "minecraft:stone"
  },
  {
    "x": 2,
    "y": 0,
    "z": 7,
    "block": "minecraft:stone"
  },
  {
    "x": 3,
    "y": 0,
    "z": 7,
    "block": "minecraft:stone"
  },
  {
    "x": 4,
    "y": 0,
    "z": 7,
    "block": "minecraft:stone"
  },
  {
    "x": 5,
    "y": 0,
    "z": 7,
    "block": "minecraft:stone"
  },
  {
    "x": 6,
    "y": 0,
    "z": 7,
    "block": "minecraft:stone"
  },
  {
    "x": 7,
    "y": 0,
    "z": 7,
    "block": "minecraft:stone"
  },
  {
    "x": 8,
    "y": 0,
    "z": 7,
    "block": "minecraft:stone"
  },
  {
    "x": 9,
    "y": 0,
    "z": 7,
    "block": "minecraft:stone"
  },
  {
    "x": 10,
    "y": 0,
    "z": 7,
    "block": "minecraft:stone"
  },
  {
    "x": 11,
    "y": 0,
    "z": 7,
    "block": "minecraft:stone"
  },
  {
    "x": 12,
    "y": 0,
    "z": 7,
    "block": "minecraft:stone"
  },
  {
    "x": 13,
    "y": 0,
    "z": 7,
    "block": "minecraft:stone"
  },
  {
    "x": 14,
    "y": 0,
    "z": 7,
    "block": "minecraft:stone"
  },
  {
    "x": 15,
    "y": 0,
    "z": 7,
    "block": "minecraft:stone"
  },
  {
    "x": 16,
    "y": 0,
    "z": 7,
    "block": "minecraft:stone"
  },
  {
    "x": 0,
    "y": 0,
    "z": 8,
    "block": "minecraft:stone"
  },
  {
    "x": 1,
    "y": 0,
    "z": 8,
    "block": "minecraft:stone"
  },
  {
    "x": 2,
    "y": 0,
    "z": 8,
    "block": "minecraft:stone"
  },
  {
    "x": 3,
    "y": 0,
    "z": 8,
    "block": "minecraft:stone"
  },
  {
    "x": 4,
    "y": 0,
    "z": 8,
    "block": "minecraft:stone"
  },
  {
    "x": 5,
    "y": 0,
    "z": 8,
    "block": "minecraft:stone"
  },
  {
    "x": 6,
    "y": 0,
    "z": 8,
    "block": "minecraft:stone"
  },
  {
    "x": 7,
    "y": 0,
    "z": 8,
    "block": "minecraft:stone"
  },
  {
    "x": 8,
    "y": 0,
    "z": 8,
    "block": "minecraft:stone"
  },
  {
    "x": 9,
    "y": 0,
    "z": 8,
    "block": "minecraft:stone"
  },
  {
    "x": 10,
    "y": 0,
    "z": 8,
    "block": "minecraft:stone"
  },
  {
    "x": 11,
    "y": 0,
    "z": 8,
    "block": "minecraft:stone"
  },
  {
    "x": 12,
    "y": 0,
    "z": 8,
    "block": "minecraft:stone"
  },
  {
    "x": 13,
    "y": 0,
    "z": 8,
    "block": "minecraft:stone"
  },
  {
    "x": 14,
    "y": 0,
    "z": 8,
    "block": "minecraft:stone"
  },
  {
    "x": 15,
    "y": 0,
    "z": 8,
    "block": "minecraft:stone"
  },
  {
    "x": 16,
    "y": 0,
    "z": 8,
    "block": "minecraft:stone"
  },
  {
    "x": 0,
    "y": 0,
    "z": 9,
    "block": "minecraft:stone"
  },
  {
    "x": 1,
    "y": 0,
    "z": 9,
    "block": "minecraft:stone"
  },
  {
    "x": 2,
    "y": 0,
    "z": 9,
    "block": "minecraft:stone"
  },
  {
    "x": 3,
    "y": 0,
    "z": 9,
    "block": "minecraft:stone"
  },
  {
    "x": 4,
    "y": 0,
    "z": 9,
    "block": "minecraft:stone"
  },
  {
    "x": 5,
    "y": 0,
    "z": 9,
    "block": "minecraft:stone"
  },
  {
    "x": 6,
    "y": 0,
    "z": 9,
    "block": "minecraft:stone"
  },
  {
    "x": 7,
    "y": 0,
    "z": 9,
    "block": "minecraft:stone"
  },
  {
    "x": 8,
    "y": 0,
    "z": 9,
    "block": "minecraft:stone"
  },
  {
    "x": 9,
    "y": 0,
    "z": 9,
    "block": "minecraft:stone"
  },
  {
    "x": 10,
    "y": 0,
    "z": 9,
    "block": "minecraft:stone"
  },
  {
    "x": 11,
    "y": 0,
    "z": 9,
    "block": "minecraft:stone"
  },
  {
    "x": 12,
    "y": 0,
    "z": 9,
    "block": "minecraft:stone"
  },
  {
    "x": 13,
    "y": 0,
    "z": 9,
    "block": "minecraft:stone"
  },
  {
    "x": 14,
    "y": 0,
    "z": 9,
    "block": "minecraft:stone"
  },
  {
    "x": 15,
    "y": 0,
    "z": 9,
    "block": "minecraft:stone"
  },
  {
    "x": 16,
    "y": 0,
    "z": 9,
    "block": "minecraft:stone"
  },
  {
    "x": 0,
    "y": 0,
    "z": 10,
    "block": "minecraft:stone"
  },
  {
    "x": 1,
    "y": 0,
    "z": 10,
    "block": "minecraft:stone"
  },
  {
    "x": 2,
    "y": 0,
    "z": 10,
    "block": "minecraft:stone"
  },
  {
    "x": 3,
    "y": 0,
    "z": 10,
    "block": "minecraft:stone"
  },
  {
    "x": 4,
    "y": 0,
    "z": 10,
    "block": "minecraft:stone"
  },
  {
    "x": 5,
    "y": 0,
    "z": 10,
    "block": "minecraft:stone"
  },
  {
    "x": 6,
    "y": 0,
    "z": 10,
    "block": "minecraft:stone"
  },
  {
    "x": 7,
    "y": 0,
    "z": 10,
    "block": "minecraft:stone"
  },
  {
    "x": 8,
    "y": 0,
    "z": 10,
    "block": "minecraft:stone"
  },
  {
    "x": 9,
    "y": 0,
    "z": 10,
    "block": "minecraft:stone"
  },
  {
    "x": 10,
    "y": 0,
    "z": 10,
    "block": "minecraft:stone"
  },
  {
    "x": 11,
    "y": 0,
    "z": 10,
    "block": "minecraft:stone"
  },
  {
    "x": 12,
    "y": 0,
    "z": 10,
    "block": "minecraft:stone"
  },
  {
    "x": 13,
    "y": 0,
    "z": 10,
    "block": "minecraft:stone"
  },
  {
    "x": 14,
    "y": 0,
    "z": 10,
    "block": "minecraft:stone"
  },
  {
    "x": 15,
    "y": 0,
    "z": 10,
    "block": "minecraft:stone"
  },
  {
    "x": 16,
    "y": 0,
    "z": 10,
    "block": "minecraft:stone"
  },
  {
    "x": 0,
    "y": 0,
    "z": 11,
    "block": "minecraft:stone"
  },
  {
    "x": 1,
    "y": 0,
    "z": 11,
    "block": "minecraft:stone"
  },
  {
    "x": 2,
    "y": 0,
    "z": 11,
    "block": "minecraft:stone"
  },
  {
    "x": 3,
    "y": 0,
    "z": 11,
    "block": "minecraft:stone"
  },
  {
    "x": 4,
    "y": 0,
    "z": 11,
    "block": "minecraft:stone"
  },
  {
    "x": 5,
    "y": 0,
    "z": 11,
    "block": "minecraft:stone"
  },
  {
    "x": 6,
    "y": 0,
    "z": 11,
    "block": "minecraft:stone"
  },
  {
    "x": 7,
    "y": 0,
    "z": 11,
    "block": "minecraft:stone"
  },
  {
    "x": 8,
    "y": 0,
    "z": 11,
    "block": "minecraft:stone"
  },
  {
    "x": 9,
    "y": 0,
    "z": 11,
    "block": "minecraft:stone"
  },
  {
    "x": 10,
    "y": 0,
    "z": 11,
    "block": "minecraft:stone"
  },
  {
    "x": 11,
    "y": 0,
    "z": 11,
    "block": "minecraft:stone"
  },
  {
    "x": 12,
    "y": 0,
    "z": 11,
    "block": "minecraft:stone"
  },
  {
    "x": 13,
    "y": 0,
    "z": 11,
    "block": "minecraft:stone"
  },
  {
    "x": 14,
    "y": 0,
    "z": 11,
    "block": "minecraft:stone"
  },
  {
    "x": 15,
    "y": 0,
    "z": 11,
    "block": "minecraft:stone"
  },
  {
    "x": 16,
    "y": 0,
    "z": 11,
    "block": "minecraft:stone"
  },
  {
    "x": 0,
    "y": 0,
    "z": 12,
    "block": "minecraft:stone"
  },
  {
    "x": 1,
    "y": 0,
    "z": 12,
    "block": "minecraft:stone"
  },
  {
    "x": 2,
    "y": 0,
    "z": 12,
    "block": "minecraft:stone"
  },
  {
    "x": 3,
    "y": 0,
    "z": 12,
    "block": "minecraft:stone"
  },
  {
    "x": 4,
    "y": 0,
    "z": 12,
    "block": "minecraft:stone"
  },
  {
    "x": 5,
    "y": 0,
    "z": 12,
    "block": "minecraft:stone"
  },
  {
    "x": 6,
    "y": 0,
    "z": 12,
    "block": "minecraft:stone"
  },
  {
    "x": 7,
    "y": 0,
    "z": 12,
    "block": "minecraft:stone"
  },
  {
    "x": 8,
    "y": 0,
    "z": 12,
    "block": "minecraft:stone"
  },
  {
    "x": 9,
    "y": 0,
    "z": 12,
    "block": "minecraft:stone"
  },
  {
    "x": 10,
    "y": 0,
    "z": 12,
    "block": "minecraft:stone"
  },
  {
    "x": 11,
    "y": 0,
    "z": 12,
    "block": "minecraft:stone"
  },
  {
    "x": 12,
    "y": 0,
    "z": 12,
    "block": "minecraft:stone"
  },
  {
    "x": 13,
    "y": 0,
    "z": 12,
    "block": "minecraft:stone"
  },
  {
    "x": 14,
    "y": 0,
    "z": 12,
    "block": "minecraft:stone"
  },
  {
    "x": 15,
    "y": 0,
    "z": 12,
    "block": "minecraft:stone"
  },
  {
    "x": 16,
    "y": 0,
    "z": 12,
    "block": "minecraft:stone"
  },
  {
    "x": 0,
    "y": 0,
    "z": 13,
    "block": "minecraft:stone"
  },
  {
    "x": 1,
    "y": 0,
    "z": 13,
    "block": "minecraft:stone"
  },
  {
    "x": 2,
    "y": 0,
    "z": 13,
    "block": "minecraft:stone"
  },
  {
    "x": 3,
    "y": 0,
    "z": 13,
    "block": "minecraft:stone"
  },
  {
    "x": 4,
    "y": 0,
    "z": 13,
    "block": "minecraft:stone"
  },
  {
    "x": 5,
    "y": 0,
    "z": 13,
    "block": "minecraft:stone"
  },
  {
    "x": 6,
    "y": 0,
    "z": 13,
    "block": "minecraft:stone"
  },
  {
    "x": 7,
    "y": 0,
    "z": 13,
    "block": "minecraft:stone"
  },
  {
    "x": 8,
    "y": 0,
    "z": 13,
    "block": "minecraft:stone"
  },
  {
    "x": 9,
    "y": 0,
    "z": 13,
    "block": "minecraft:stone"
  },
  {
    "x": 10,
    "y": 0,
    "z": 13,
    "block": "minecraft:stone"
  },
  {
    "x": 11,
    "y": 0,
    "z": 13,
    "block": "minecraft:stone"
  },
  {
    "x": 12,
    "y": 0,
    "z": 13,
    "block": "minecraft:stone"
  },
  {
    "x": 13,
    "y": 0,
    "z": 13,
    "block": "minecraft:stone"
  },
  {
    "x": 14,
    "y": 0,
    "z": 13,
    "block": "minecraft:stone"
  },
  {
    "x": 15,
    "y": 0,
    "z": 13,
    "block": "minecraft:stone"
  },
  {
    "x": 16,
    "y": 0,
    "z": 13,
    "block": "minecraft:stone"
  },
  {
    "x": 0,
    "y": 0,
    "z": 14,
    "block": "minecraft:stone"
  },
  {
    "x": 1,
    "y": 0,
    "z": 14,
    "block": "minecraft:stone"
  },
  {
    "x": 2,
    "y": 0,
    "z": 14,
    "block": "minecraft:stone"
  },
  {
    "x": 3,
    "y": 0,
    "z": 14,
    "block": "minecraft:stone"
  },
  {
    "x": 4,
    "y": 0,
    "z": 14,
    "block": "minecraft:stone"
  },
  {
    "x": 5,
    "y": 0,
    "z": 14,
    "block": "minecraft:stone"
  },
  {
    "x": 6,
    "y": 0,
    "z": 14,
    "block": "minecraft:stone"
  },
  {
    "x": 7,
    "y": 0,
    "z": 14,
    "block": "minecraft:stone"
  },
  {
    "x": 8,
    "y": 0,
    "z": 14,
    "block": "minecraft:stone"
  },
  {
    "x": 9,
    "y": 0,
    "z": 14,
    "block": "minecraft:stone"
  },
  {
    "x": 10,
    "y": 0,
    "z": 14,
    "block": "minecraft:stone"
  },
  {
    "x": 11,
    "y": 0,
    "z": 14,
    "block": "minecraft:stone"
  },
  {
    "x": 12,
    "y": 0,
    "z": 14,
    "block": "minecraft:stone"
  },
  {
    "x": 13,
    "y": 0,
    "z": 14,
    "block": "minecraft:stone"
  },
  {
    "x": 14,
    "y": 0,
    "z": 14,
    "block": "minecraft:stone"
  },
  {
    "x": 15,
    "y": 0,
    "z": 14,
    "block": "minecraft:stone"
  },
  {
    "x": 16,
    "y": 0,
    "z": 14,
    "block": "minecraft:stone"
  },
  {
    "x": 0,
    "y": 0,
    "z": 15,
    "block": "minecraft:stone"
  },
  {
    "x": 1,
    "y": 0,
    "z": 15,
    "block": "minecraft:stone"
  },
  {
    "x": 2,
    "y": 0,
    "z": 15,
    "block": "minecraft:stone"
  },
  {
    "x": 3,
    "y": 0,
    "z": 15,
    "block": "minecraft:stone"
  },
  {
    "x": 4,
    "y": 0,
    "z": 15,
    "block": "minecraft:stone"
  },
  {
    "x": 5,
    "y": 0,
    "z": 15,
    "block": "minecraft:stone"
  },
  {
    "x": 6,
    "y": 0,
    "z": 15,
    "block": "minecraft:stone"
  },
  {
    "x": 7,
    "y": 0,
    "z": 15,
    "block": "minecraft:stone"
  },
  {
    "x": 8,
    "y": 0,
    "z": 15,
    "block": "minecraft:stone"
  },
  {
    "x": 9,
    "y": 0,
    "z": 15,
    "block": "minecraft:stone"
  },
  {
    "x": 10,
    "y": 0,
    "z": 15,
    "block": "minecraft:stone"
  },
  {
    "x": 11,
    "y": 0,
    "z": 15,
    "block": "minecraft:stone"
  },
  {
    "x": 12,
    "y": 0,
    "z": 15,
    "block": "minecraft:stone"
  },
  {
    "x": 13,
    "y": 0,
    "z": 15,
    "block": "minecraft:stone"
  },
  {
    "x": 14,
    "y": 0,
    "z": 15,
    "block": "minecraft:stone"
  },
  {
    "x": 15,
    "y": 0,
    "z": 15,
    "block": "minecraft:stone"
  },
  {
    "x": 16,
    "y": 0,
    "z": 15,
    "block": "minecraft:stone"
  },
  {
    "x": 0,
    "y": 0,
    "z": 16,
    "block": "minecraft:stone"
  },
  {
    "x": 1,
    "y": 0,
    "z": 16,
    "block": "minecraft:stone"
  },
  {
    "x": 2,
    "y": 0,
    "z": 16,
    "block": "minecraft:stone"
  },
  {
    "x": 3,
    "y": 0,
    "z": 16,
    "block": "minecraft:stone"
  },
  {
    "x": 4,
    "y": 0,
    "z": 16,
    "block": "minecraft:stone"
  },
  {
    "x": 5,
    "y": 0,
    "z": 16,
    "block": "minecraft:stone"
  },
  {
    "x": 6,
    "y": 0,
    "z": 16,
    "block": "minecraft:stone"
  },
  {
    "x": 7,
    "y": 0,
    "z": 16,
    "block": "minecraft:stone"
  },
  {
    "x": 8,
    "y": 0,
    "z": 16,
    "block": "minecraft:stone"
  },
  {
    "x": 9,
    "y": 0,
    "z": 16,
    "block": "minecraft:stone"
  },
  {
    "x": 10,
    "y": 0,
    "z": 16,
    "block": "minecraft:stone"
  },
  {
    "x": 11,
    "y": 0,
    "z": 16,
    "block": "minecraft:stone"
  },
  {
    "x": 12,
    "y": 0,
    "z": 16,
    "block": "minecraft:stone"
  },
  {
    "x": 13,
    "y": 0,
    "z": 16,
    "block": "minecraft:stone"
  },
  {
    "x": 14,
    "y": 0,
    "z": 16,
    "block": "minecraft:stone"
  },
  {
    "x": 15,
    "y": 0,
    "z": 16,
    "block": "minecraft:stone"
  },
  {
    "x": 16,
    "y": 0,
    "z": 16,
    "block": "minecraft:stone"
  },
  {
    "x": 0,
    "y": 0,
    "z": 17,
    "block": "minecraft:stone"
  },
  {
    "x": 1,
    "y": 0,
    "z": 17,
    "block": "minecraft:stone"
  },
  {
    "x": 2,
    "y": 0,
    "z": 17,
    "block": "minecraft:stone"
  },
  {
    "x": 3,
    "y": 0,
    "z": 17,
    "block": "minecraft:stone"
  },
  {
    "x": 4,
    "y": 0,
    "z": 17,
    "block": "minecraft:stone"
  },
  {
    "x": 5,
    "y": 0,
    "z": 17,
    "block": "minecraft:stone"
  },
  {
    "x": 6,
    "y": 0,
    "z": 17,
    "block": "minecraft:stone"
  },
  {
    "x": 7,
    "y": 0,
    "z": 17,
    "block": "minecraft:stone"
  },
  {
    "x": 8,
    "y": 0,
    "z": 17,
    "block": "minecraft:stone"
  },
  {
    "x": 9,
    "y": 0,
    "z": 17,
    "block": "minecraft:stone"
  },
  {
    "x": 10,
    "y": 0,
    "z": 17,
    "block": "minecraft:stone"
  },
  {
    "x": 11,
    "y": 0,
    "z": 17,
    "block": "minecraft:stone"
  },
  {
    "x": 12,
    "y": 0,
    "z": 17,
    "block": "minecraft:stone"
  },
  {
    "x": 13,
    "y": 0,
    "z": 17,
    "block": "minecraft:stone"
  },
  {
    "x": 14,
    "y": 0,
    "z": 17,
    "block": "minecraft:stone"
  },
  {
    "x": 15,
    "y": 0,
    "z": 17,
    "block": "minecraft:stone"
  },
  {
    "x": 16,
    "y": 0,
    "z": 17,
    "block": "minecraft:stone"
  },
  {
    "x": 0,
    "y": 0,
    "z": 18,
    "block": "minecraft:stone"
  },
  {
    "x": 1,
    "y": 0,
    "z": 18,
    "block": "minecraft:stone"
  },
  {
    "x": 2,
    "y": 0,
    "z": 18,
    "block": "minecraft:stone"
  },
  {
    "x": 3,
    "y": 0,
    "z": 18,
    "block": "minecraft:stone"
  },
  {
    "x": 4,
    "y": 0,
    "z": 18,
    "block": "minecraft:stone"
  },
  {
    "x": 5,
    "y": 0,
    "z": 18,
    "block": "minecraft:stone"
  },
  {
    "x": 6,
    "y": 0,
    "z": 18,
    "block": "minecraft:stone"
  },
  {
    "x": 7,
    "y": 0,
    "z": 18,
    "block": "minecraft:stone"
  },
  {
    "x": 8,
    "y": 0,
    "z": 18,
    "block": "minecraft:stone"
  },
  {
    "x": 9,
    "y": 0,
    "z": 18,
    "block": "minecraft:stone"
  },
  {
    "x": 10,
    "y": 0,
    "z": 18,
    "block": "minecraft:stone"
  },
  {
    "x": 11,
    "y": 0,
    "z": 18,
    "block": "minecraft:stone"
  },
  {
    "x": 12,
    "y": 0,
    "z": 18,
    "block": "minecraft:stone"
  },
  {
    "x": 13,
    "y": 0,
    "z": 18,
    "block": "minecraft:stone"
  },
  {
    "x": 14,
    "y": 0,
    "z": 18,
    "block": "minecraft:stone"
  },
  {
    "x": 15,
    "y": 0,
    "z": 18,
    "block": "minecraft:stone"
  },
  {
    "x": 16,
    "y": 0,
    "z": 18,
    "block": "minecraft:stone"
  },
  {
    "x": 0,
    "y": 0,
    "z": 19,
    "block": "minecraft:stone"
  },
  {
    "x": 1,
    "y": 0,
    "z": 19,
    "block": "minecraft:stone"
  },
  {
    "x": 2,
    "y": 0,
    "z": 19,
    "block": "minecraft:stone"
  },
  {
    "x": 3,
    "y": 0,
    "z": 19,
    "block": "minecraft:stone"
  },
  {
    "x": 4,
    "y": 0,
    "z": 19,
    "block": "minecraft:stone"
  },
  {
    "x": 5,
    "y": 0,
    "z": 19,
    "block": "minecraft:stone"
  },
  {
    "x": 6,
    "y": 0,
    "z": 19,
    "block": "minecraft:stone"
  },
  {
    "x": 7,
    "y": 0,
    "z": 19,
    "block": "minecraft:stone"
  },
  {
    "x": 8,
    "y": 0,
    "z": 19,
    "block": "minecraft:stone"
  },
  {
    "x": 9,
    "y": 0,
    "z": 19,
    "block": "minecraft:stone"
  },
  {
    "x": 10,
    "y": 0,
    "z": 19,
    "block": "minecraft:stone"
  },
  {
    "x": 11,
    "y": 0,
    "z": 19,
    "block": "minecraft:stone"
  },
  {
    "x": 12,
    "y": 0,
    "z": 19,
    "block": "minecraft:stone"
  },
  {
    "x": 13,
    "y": 0,
    "z": 19,
    "block": "minecraft:stone"
  },
  {
    "x": 14,
    "y": 0,
    "z": 19,
    "block": "minecraft:stone"
  },
  {
    "x": 15,
    "y": 0,
    "z": 19,
    "block": "minecraft:stone"
  },
  {
    "x": 16,
    "y": 0,
    "z": 19,
    "block": "minecraft:stone"
  },
  {
    "x": 0,
    "y": 0,
    "z": 20,
    "block": "minecraft:stone"
  },
  {
    "x": 1,
    "y": 0,
    "z": 20,
    "block": "minecraft:stone"
  },
  {
    "x": 2,
    "y": 0,
    "z": 20,
    "block": "minecraft:stone"
  },
  {
    "x": 3,
    "y": 0,
    "z": 20,
    "block": "minecraft:stone"
  },
  {
    "x": 4,
    "y": 0,
    "z": 20,
    "block": "minecraft:stone"
  },
  {
    "x": 5,
    "y": 0,
    "z": 20,
    "block": "minecraft:stone"
  },
  {
    "x": 6,
    "y": 0,
    "z": 20,
    "block": "minecraft:stone"
  },
  {
    "x": 7,
    "y": 0,
    "z": 20,
    "block": "minecraft:stone"
  },
  {
    "x": 8,
    "y": 0,
    "z": 20,
    "block": "minecraft:stone"
  },
  {
    "x": 9,
    "y": 0,
    "z": 20,
    "block": "minecraft:stone"
  },
  {
    "x": 10,
    "y": 0,
    "z": 20,
    "block": "minecraft:stone"
  },
  {
    "x": 11,
    "y": 0,
    "z": 20,
    "block": "minecraft:stone"
  },
  {
    "x": 12,
    "y": 0,
    "z": 20,
    "block": "minecraft:stone"
  },
  {
    "x": 13,
    "y": 0,
    "z": 20,
    "block": "minecraft:stone"
  },
  {
    "x": 14,
    "y": 0,
    "z": 20,
    "block": "minecraft:stone"
  },
  {
    "x": 15,
    "y": 0,
    "z": 20,
    "block": "minecraft:stone"
  },
  {
    "x": 16,
    "y": 0,
    "z": 20,
    "block": "minecraft:stone"
  },
  {
    "x": 0,
    "y": 0,
    "z": 21,
    "block": "minecraft:stone"
  },
  {
    "x": 1,
    "y": 0,
    "z": 21,
    "block": "minecraft:stone"
  },
  {
    "x": 2,
    "y": 0,
    "z": 21,
    "block": "minecraft:stone"
  },
  {
    "x": 3,
    "y": 0,
    "z": 21,
    "block": "minecraft:stone"
  },
  {
    "x": 4,
    "y": 0,
    "z": 21,
    "block": "minecraft:stone"
  },
  {
    "x": 5,
    "y": 0,
    "z": 21,
    "block": "minecraft:stone"
  },
  {
    "x": 6,
    "y": 0,
    "z": 21,
    "block": "minecraft:stone"
  },
  {
    "x": 7,
    "y": 0,
    "z": 21,
    "block": "minecraft:stone"
  },
  {
    "x": 8,
    "y": 0,
    "z": 21,
    "block": "minecraft:stone"
  },
  {
    "x": 9,
    "y": 0,
    "z": 21,
    "block": "minecraft:stone"
  },
  {
    "x": 10,
    "y": 0,
    "z": 21,
    "block": "minecraft:stone"
  },
  {
    "x": 11,
    "y": 0,
    "z": 21,
    "block": "minecraft:stone"
  },
  {
    "x": 12,
    "y": 0,
    "z": 21,
    "block": "minecraft:stone"
  },
  {
    "x": 13,
    "y": 0,
    "z": 21,
    "block": "minecraft:stone"
  },
  {
    "x": 14,
    "y": 0,
    "z": 21,
    "block": "minecraft:stone"
  },
  {
    "x": 15,
    "y": 0,
    "z": 21,
    "block": "minecraft:stone"
  },
  {
    "x": 16,
    "y": 0,
    "z": 21,
    "block": "minecraft:stone"
  },
  {
    "x": 0,
    "y": 0,
    "z": 22,
    "block": "minecraft:stone"
  },
  {
    "x": 1,
    "y": 0,
    "z": 22,
    "block": "minecraft:stone"
  },
  {
    "x": 2,
    "y": 0,
    "z": 22,
    "block": "minecraft:stone"
  },
  {
    "x": 3,
    "y": 0,
    "z": 22,
    "block": "minecraft:stone"
  },
  {
    "x": 4,
    "y": 0,
    "z": 22,
    "block": "minecraft:stone"
  },
  {
    "x": 5,
    "y": 0,
    "z": 22,
    "block": "minecraft:stone"
  },
  {
    "x": 6,
    "y": 0,
    "z": 22,
    "block": "minecraft:stone"
  },
  {
    "x": 7,
    "y": 0,
    "z": 22,
    "block": "minecraft:stone"
  },
  {
    "x": 8,
    "y": 0,
    "z": 22,
    "block": "minecraft:stone"
  },
  {
    "x": 9,
    "y": 0,
    "z": 22,
    "block": "minecraft:stone"
  },
  {
    "x": 10,
    "y": 0,
    "z": 22,
    "block": "minecraft:stone"
  },
  {
    "x": 11,
    "y": 0,
    "z": 22,
    "block": "minecraft:stone"
  },
  {
    "x": 12,
    "y": 0,
    "z": 22,
    "block": "minecraft:stone"
  },
  {
    "x": 13,
    "y": 0,
    "z": 22,
    "block": "minecraft:stone"
  },
  {
    "x": 14,
    "y": 0,
    "z": 22,
    "block": "minecraft:stone"
  },
  {
    "x": 15,
    "y": 0,
    "z": 22,
    "block": "minecraft:stone"
  },
  {
    "x": 16,
    "y": 0,
    "z": 22,
    "block": "minecraft:stone"
  },
  {
    "x": 0,
    "y": 0,
    "z": 23,
    "block": "minecraft:stone"
  },
  {
    "x": 1,
    "y": 0,
    "z": 23,
    "block": "minecraft:stone"
  },
  {
    "x": 2,
    "y": 0,
    "z": 23,
    "block": "minecraft:stone"
  },
  {
    "x": 3,
    "y": 0,
    "z": 23,
    "block": "minecraft:stone"
  },
  {
    "x": 4,
    "y": 0,
    "z": 23,
    "block": "minecraft:stone"
  },
  {
    "x": 5,
    "y": 0,
    "z": 23,
    "block": "minecraft:stone"
  },
  {
    "x": 6,
    "y": 0,
    "z": 23,
    "block": "minecraft:stone"
  },
  {
    "x": 7,
    "y": 0,
    "z": 23,
    "block": "minecraft:stone"
  },
  {
    "x": 8,
    "y": 0,
    "z": 23,
    "block": "minecraft:stone"
  },
  {
    "x": 9,
    "y": 0,
    "z": 23,
    "block": "minecraft:stone"
  },
  {
    "x": 10,
    "y": 0,
    "z": 23,
    "block": "minecraft:stone"
  },
  {
    "x": 11,
    "y": 0,
    "z": 23,
    "block": "minecraft:stone"
  },
  {
    "x": 12,
    "y": 0,
    "z": 23,
    "block": "minecraft:stone"
  },
  {
    "x": 13,
    "y": 0,
    "z": 23,
    "block": "minecraft:stone"
  },
  {
    "x": 14,
    "y": 0,
    "z": 23,
    "block": "minecraft:stone"
  },
  {
    "x": 15,
    "y": 0,
    "z": 23,
    "block": "minecraft:stone"
  },
  {
    "x": 16,
    "y": 0,
    "z": 23,
    "block": "minecraft:stone"
  },
  {
    "x": 0,
    "y": 0,
    "z": 24,
    "block": "minecraft:stone"
  },
  {
    "x": 1,
    "y": 0,
    "z": 24,
    "block": "minecraft:stone"
  },
  {
    "x": 2,
    "y": 0,
    "z": 24,
    "block": "minecraft:stone"
  },
  {
    "x": 3,
    "y": 0,
    "z": 24,
    "block": "minecraft:stone"
  },
  {
    "x": 4,
    "y": 0,
    "z": 24,
    "block": "minecraft:stone"
  },
  {
    "x": 5,
    "y": 0,
    "z": 24,
    "block": "minecraft:stone"
  },
  {
    "x": 6,
    "y": 0,
    "z": 24,
    "block": "minecraft:stone"
  },
  {
    "x": 7,
    "y": 0,
    "z": 24,
    "block": "minecraft:stone"
  },
  {
    "x": 8,
    "y": 0,
    "z": 24,
    "block": "minecraft:stone"
  },
  {
    "x": 9,
    "y": 0,
    "z": 24,
    "block": "minecraft:stone"
  },
  {
    "x": 10,
    "y": 0,
    "z": 24,
    "block": "minecraft:stone"
  },
  {
    "x": 11,
    "y": 0,
    "z": 24,
    "block": "minecraft:stone"
  },
  {
    "x": 12,
    "y": 0,
    "z": 24,
    "block": "minecraft:stone"
  },
  {
    "x": 13,
    "y": 0,
    "z": 24,
    "block": "minecraft:stone"
  },
  {
    "x": 14,
    "y": 0,
    "z": 24,
    "block": "minecraft:stone"
  },
  {
    "x": 15,
    "y": 0,
    "z": 24,
    "block": "minecraft:stone"
  },
  {
    "x": 16,
    "y": 0,
    "z": 24,
    "block": "minecraft:stone"
  },
  {
    "x": 0,
    "y": 0,
    "z": 25,
    "block": "minecraft:stone"
  },
  {
    "x": 1,
    "y": 0,
    "z": 25,
    "block": "minecraft:stone"
  },
  {
    "x": 2,
    "y": 0,
    "z": 25,
    "block": "minecraft:stone"
  },
  {
    "x": 3,
    "y": 0,
    "z": 25,
    "block": "minecraft:stone"
  },
  {
    "x": 4,
    "y": 0,
    "z": 25,
    "block": "minecraft:stone"
  },
  {
    "x": 5,
    "y": 0,
    "z": 25,
    "block": "minecraft:stone"
  },
  {
    "x": 6,
    "y": 0,
    "z": 25,
    "block": "minecraft:stone"
  },
  {
    "x": 7,
    "y": 0,
    "z": 25,
    "block": "minecraft:stone"
  },
  {
    "x": 8,
    "y": 0,
    "z": 25,
    "block": "minecraft:stone"
  },
  {
    "x": 9,
    "y": 0,
    "z": 25,
    "block": "minecraft:stone"
  },
  {
    "x": 10,
    "y": 0,
    "z": 25,
    "block": "minecraft:stone"
  },
  {
    "x": 11,
    "y": 0,
    "z": 25,
    "block": "minecraft:stone"
  },
  {
    "x": 12,
    "y": 0,
    "z": 25,
    "block": "minecraft:stone"
  },
  {
    "x": 13,
    "y": 0,
    "z": 25,
    "block": "minecraft:stone"
  },
  {
    "x": 14,
    "y": 0,
    "z": 25,
    "block": "minecraft:stone"
  },
  {
    "x": 15,
    "y": 0,
    "z": 25,
    "block": "minecraft:stone"
  },
  {
    "x": 16,
    "y": 0,
    "z": 25,
    "block": "minecraft:stone"
  },
  {
    "x": 0,
    "y": 0,
    "z": 26,
    "block": "minecraft:stone"
  },
  {
    "x": 1,
    "y": 0,
    "z": 26,
    "block": "minecraft:stone"
  },
  {
    "x": 2,
    "y": 0,
    "z": 26,
    "block": "minecraft:stone"
  },
  {
    "x": 3,
    "y": 0,
    "z": 26,
    "block": "minecraft:stone"
  },
  {
    "x": 4,
    "y": 0,
    "z": 26,
    "block": "minecraft:stone"
  },
  {
    "x": 5,
    "y": 0,
    "z": 26,
    "block": "minecraft:stone"
  },
  {
    "x": 6,
    "y": 0,
    "z": 26,
    "block": "minecraft:stone"
  },
  {
    "x": 7,
    "y": 0,
    "z": 26,
    "block": "minecraft:stone"
  },
  {
    "x": 8,
    "y": 0,
    "z": 26,
    "block": "minecraft:stone"
  },
  {
    "x": 9,
    "y": 0,
    "z": 26,
    "block": "minecraft:stone"
  },
  {
    "x": 10,
    "y": 0,
    "z": 26,
    "block": "minecraft:stone"
  },
  {
    "x": 11,
    "y": 0,
    "z": 26,
    "block": "minecraft:stone"
  },
  {
    "x": 12,
    "y": 0,
    "z": 26,
    "block": "minecraft:stone"
  },
  {
    "x": 13,
    "y": 0,
    "z": 26,
    "block": "minecraft:stone"
  },
  {
    "x": 14,
    "y": 0,
    "z": 26,
    "block": "minecraft:stone"
  },
  {
    "x": 15,
    "y": 0,
    "z": 26,
    "block": "minecraft:stone"
  },
  {
    "x": 16,
    "y": 0,
    "z": 26,
    "block": "minecraft:stone"
  },
  {
    "x": 0,
    "y": 0,
    "z": 27,
    "block": "minecraft:stone"
  },
  {
    "x": 1,
    "y": 0,
    "z": 27,
    "block": "minecraft:stone"
  },
  {
    "x": 2,
    "y": 0,
    "z": 27,
    "block": "minecraft:stone"
  },
  {
    "x": 3,
    "y": 0,
    "z": 27,
    "block": "minecraft:stone"
  },
  {
    "x": 4,
    "y": 0,
    "z": 27,
    "block": "minecraft:stone"
  },
  {
    "x": 5,
    "y": 0,
    "z": 27,
    "block": "minecraft:stone"
  },
  {
    "x": 6,
    "y": 0,
    "z": 27,
    "block": "minecraft:stone"
  },
  {
    "x": 7,
    "y": 0,
    "z": 27,
    "block": "minecraft:stone"
  },
  {
    "x": 8,
    "y": 0,
    "z": 27,
    "block": "minecraft:stone"
  },
  {
    "x": 9,
    "y": 0,
    "z": 27,
    "block": "minecraft:stone"
  },
  {
    "x": 10,
    "y": 0,
    "z": 27,
    "block": "minecraft:stone"
  },
  {
    "x": 11,
    "y": 0,
    "z": 27,
    "block": "minecraft:stone"
  },
  {
    "x": 12,
    "y": 0,
    "z": 27,
    "block": "minecraft:stone"
  },
  {
    "x": 13,
    "y": 0,
    "z": 27,
    "block": "minecraft:stone"
  },
  {
    "x": 14,
    "y": 0,
    "z": 27,
    "block": "minecraft:stone"
  },
  {
    "x": 15,
    "y": 0,
    "z": 27,
    "block": "minecraft:stone"
  },
  {
    "x": 16,
    "y": 0,
    "z": 27,
    "block": "minecraft:stone"
  },
  {
    "x": 0,
    "y": 0,
    "z": 28,
    "block": "minecraft:stone"
  },
  {
    "x": 1,
    "y": 0,
    "z": 28,
    "block": "minecraft:stone"
  },
  {
    "x": 2,
    "y": 0,
    "z": 28,
    "block": "minecraft:stone"
  },
  {
    "x": 3,
    "y": 0,
    "z": 28,
    "block": "minecraft:stone"
  },
  {
    "x": 4,
    "y": 0,
    "z": 28,
    "block": "minecraft:stone"
  },
  {
    "x": 5,
    "y": 0,
    "z": 28,
    "block": "minecraft:stone"
  },
  {
    "x": 6,
    "y": 0,
    "z": 28,
    "block": "minecraft:stone"
  },
  {
    "x": 7,
    "y": 0,
    "z": 28,
    "block": "minecraft:stone"
  },
  {
    "x": 8,
    "y": 0,
    "z": 28,
    "block": "minecraft:stone"
  },
  {
    "x": 9,
    "y": 0,
    "z": 28,
    "block": "minecraft:stone"
  },
  {
    "x": 10,
    "y": 0,
    "z": 28,
    "block": "minecraft:stone"
  },
  {
    "x": 11,
    "y": 0,
    "z": 28,
    "block": "minecraft:stone"
  },
  {
    "x": 12,
    "y": 0,
    "z": 28,
    "block": "minecraft:stone"
  },
  {
    "x": 13,
    "y": 0,
    "z": 28,
    "block": "minecraft:stone"
  },
  {
    "x": 14,
    "y": 0,
    "z": 28,
    "block": "minecraft:stone"
  },
  {
    "x": 15,
    "y": 0,
    "z": 28,
    "block": "minecraft:stone"
  },
  {
    "x": 16,
    "y": 0,
    "z": 28,
    "block": "minecraft:stone"
  },
  {
    "x": 0,
    "y": 0,
    "z": 29,
    "block": "minecraft:stone"
  },
  {
    "x": 1,
    "y": 0,
    "z": 29,
    "block": "minecraft:stone"
  },
  {
    "x": 2,
    "y": 0,
    "z": 29,
    "block": "minecraft:stone"
  },
  {
    "x": 3,
    "y": 0,
    "z": 29,
    "block": "minecraft:stone"
  },
  {
    "x": 4,
    "y": 0,
    "z": 29,
    "block": "minecraft:stone"
  },
  {
    "x": 5,
    "y": 0,
    "z": 29,
    "block": "minecraft:stone"
  },
  {
    "x": 6,
    "y": 0,
    "z": 29,
    "block": "minecraft:stone"
  },
  {
    "x": 7,
    "y": 0,
    "z": 29,
    "block": "minecraft:stone"
  },
  {
    "x": 8,
    "y": 0,
    "z": 29,
    "block": "minecraft:stone"
  },
  {
    "x": 9,
    "y": 0,
    "z": 29,
    "block": "minecraft:stone"
  },
  {
    "x": 10,
    "y": 0,
    "z": 29,
    "block": "minecraft:stone"
  },
  {
    "x": 11,
    "y": 0,
    "z": 29,
    "block": "minecraft:stone"
  },
  {
    "x": 12,
    "y": 0,
    "z": 29,
    "block": "minecraft:stone"
  },
  {
    "x": 13,
    "y": 0,
    "z": 29,
    "block": "minecraft:stone"
  },
  {
    "x": 14,
    "y": 0,
    "z": 29,
    "block": "minecraft:stone"
  },
  {
    "x": 15,
    "y": 0,
    "z": 29,
    "block": "minecraft:stone"
  },
  {
    "x": 16,
    "y": 0,
    "z": 29,
    "block": "minecraft:stone"
  },
  {
    "x": 0,
    "y": 0,
    "z": 30,
    "block": "minecraft:stone"
  },
  {
    "x": 1,
    "y": 0,
    "z": 30,
    "block": "minecraft:stone"
  },
  {
    "x": 2,
    "y": 0,
    "z": 30,
    "block": "minecraft:stone"
  },
  {
    "x": 3,
    "y": 0,
    "z": 30,
    "block": "minecraft:stone"
  },
  {
    "x": 4,
    "y": 0,
    "z": 30,
    "block": "minecraft:stone"
  },
  {
    "x": 5,
    "y": 0,
    "z": 30,
    "block": "minecraft:stone"
  },
  {
    "x": 6,
    "y": 0,
    "z": 30,
    "block": "minecraft:stone"
  },
  {
    "x": 7,
    "y": 0,
    "z": 30,
    "block": "minecraft:stone"
  },
  {
    "x": 8,
    "y": 0,
    "z": 30,
    "block": "minecraft:stone"
  },
  {
    "x": 9,
    "y": 0,
    "z": 30,
    "block": "minecraft:stone"
  },
  {
    "x": 10,
    "y": 0,
    "z": 30,
    "block": "minecraft:stone"
  },
  {
    "x": 11,
    "y": 0,
    "z": 30,
    "block": "minecraft:stone"
  },
  {
    "x": 12,
    "y": 0,
    "z": 30,
    "block": "minecraft:stone"
  },
  {
    "x": 13,
    "y": 0,
    "z": 30,
    "block": "minecraft:stone"
  },
  {
    "x": 14,
    "y": 0,
    "z": 30,
    "block": "minecraft:stone"
  },
  {
    "x": 15,
    "y": 0,
    "z": 30,
    "block": "minecraft:stone"
  },
  {
    "x": 16,
    "y": 0,
    "z": 30,
    "block": "minecraft:stone"
  },
  {
    "x": 0,
    "y": 0,
    "z": 31,
    "block": "minecraft:stone"
  },
  {
    "x": 1,
    "y": 0,
    "z": 31,
    "block": "minecraft:stone"
  },
  {
    "x": 2,
    "y": 0,
    "z": 31,
    "block": "minecraft:stone"
  },
  {
    "x": 3,
    "y": 0,
    "z": 31,
    "block": "minecraft:stone"
  },
  {
    "x": 4,
    "y": 0,
    "z": 31,
    "block": "minecraft:stone"
  },
  {
    "x": 5,
    "y": 0,
    "z": 31,
    "block": "minecraft:stone"
  },
  {
    "x": 6,
    "y": 0,
    "z": 31,
    "block": "minecraft:stone"
  },
  {
    "x": 7,
    "y": 0,
    "z": 31,
    "block": "minecraft:stone"
  },
  {
    "x": 8,
    "y": 0,
    "z": 31,
    "block": "minecraft:stone"
  },
  {
    "x": 9,
    "y": 0,
    "z": 31,
    "block": "minecraft:stone"
  },
  {
    "x": 10,
    "y": 0,
    "z": 31,
    "block": "minecraft:stone"
  },
  {
    "x": 11,
    "y": 0,
    "z": 31,
    "block": "minecraft:stone"
  },
  {
    "x": 12,
    "y": 0,
    "z": 31,
    "block": "minecraft:stone"
  },
  {
    "x": 13,
    "y": 0,
    "z": 31,
    "block": "minecraft:stone"
  },
  {
    "x": 14,
    "y": 0,
    "z": 31,
    "block": "minecraft:stone"
  },
  {
    "x": 15,
    "y": 0,
    "z": 31,
    "block": "minecraft:stone"
  },
  {
    "x": 16,
    "y": 0,
    "z": 31,
    "block": "minecraft:stone"
  },
  {
    "x": 0,
    "y": 0,
    "z": 32,
    "block": "minecraft:stone"
  },
  {
    "x": 1,
    "y": 0,
    "z": 32,
    "block": "minecraft:stone"
  },
  {
    "x": 2,
    "y": 0,
    "z": 32,
    "block": "minecraft:stone"
  },
  {
    "x": 3,
    "y": 0,
    "z": 32,
    "block": "minecraft:stone"
  },
  {
    "x": 4,
    "y": 0,
    "z": 32,
    "block": "minecraft:stone"
  },
  {
    "x": 5,
    "y": 0,
    "z": 32,
    "block": "minecraft:stone"
  },
  {
    "x": 6,
    "y": 0,
    "z": 32,
    "block": "minecraft:stone"
  },
  {
    "x": 7,
    "y": 0,
    "z": 32,
    "block": "minecraft:stone"
  },
  {
    "x": 8,
    "y": 0,
    "z": 32,
    "block": "minecraft:stone"
  },
  {
    "x": 9,
    "y": 0,
    "z": 32,
    "block": "minecraft:stone"
  },
  {
    "x": 10,
    "y": 0,
    "z": 32,
    "block": "minecraft:stone"
  },
  {
    "x": 11,
    "y": 0,
    "z": 32,
    "block": "minecraft:stone"
  },
  {
    "x": 12,
    "y": 0,
    "z": 32,
    "block": "minecraft:stone"
  },
  {
    "x": 13,
    "y": 0,
    "z": 32,
    "block": "minecraft:stone"
  },
  {
    "x": 14,
    "y": 0,
    "z": 32,
    "block": "minecraft:stone"
  },
  {
    "x": 15,
    "y": 0,
    "z": 32,
    "block": "minecraft:stone"
  },
  {
    "x": 16,
    "y": 0,
    "z": 32,
    "block": "minecraft:stone"
  },
  {
    "x": 0,
    "y": 0,
    "z": 33,
    "block": "minecraft:stone"
  },
  {
    "x": 1,
    "y": 0,
    "z": 33,
    "block": "minecraft:stone"
  },
  {
    "x": 2,
    "y": 0,
    "z": 33,
    "block": "minecraft:stone"
  },
  {
    "x": 3,
    "y": 0,
    "z": 33,
    "block": "minecraft:stone"
  },
  {
    "x": 4,
    "y": 0,
    "z": 33,
    "block": "minecraft:stone"
  },
  {
    "x": 5,
    "y": 0,
    "z": 33,
    "block": "minecraft:stone"
  },
  {
    "x": 6,
    "y": 0,
    "z": 33,
    "block": "minecraft:stone"
  },
  {
    "x": 7,
    "y": 0,
    "z": 33,
    "block": "minecraft:stone"
  },
  {
    "x": 8,
    "y": 0,
    "z": 33,
    "block": "minecraft:stone"
  },
  {
    "x": 9,
    "y": 0,
    "z": 33,
    "block": "minecraft:blue_stained_glass"
  },
  {
    "x": 10,
    "y": 0,
    "z": 33,
    "block": "minecraft:blue_stained_glass"
  },
  {
    "x": 11,
    "y": 0,
    "z": 33,
    "block": "minecraft:blue_stained_glass"
  },
  {
    "x": 12,
    "y": 0,
    "z": 33,
    "block": "minecraft:stone"
  },
  {
    "x": 13,
    "y": 0,
    "z": 33,
    "block": "minecraft:stone"
  },
  {
    "x": 14,
    "y": 0,
    "z": 33,
    "block": "minecraft:stone"
  },
  {
    "x": 15,
    "y": 0,
    "z": 33,
    "block": "minecraft:stone"
  },
  {
    "x": 16,
    "y": 0,
    "z": 33,
    "block": "minecraft:stone"
  },
  {
    "x": 0,
    "y": 1,
    "z": 0,
    "block": "minecraft:stone"
  },
  {
    "x": 1,
    "y": 1,
    "z": 0,
    "block": "minecraft:stone"
  },
  {
    "x": 2,
    "y": 1,
    "z": 0,
    "block": "minecraft:stone"
  },
  {
    "x": 3,
    "y": 1,
    "z": 0,
    "block": "minecraft:stone"
  },
  {
    "x": 4,
    "y": 1,
    "z": 0,
    "block": "minecraft:stone"
  },
  {
    "x": 5,
    "y": 1,
    "z": 0,
    "block": "minecraft:stone"
  },
  {
    "x": 6,
    "y": 1,
    "z": 0,
    "block": "minecraft:stone"
  },
  {
    "x": 7,
    "y": 1,
    "z": 0,
    "block": "minecraft:stone"
  },
  {
    "x": 8,
    "y": 1,
    "z": 0,
    "block": "minecraft:stone"
  },
  {
    "x": 9,
    "y": 1,
    "z": 0,
    "block": "minecraft:stone"
  },
  {
    "x": 10,
    "y": 1,
    "z": 0,
    "block": "minecraft:stone"
  },
  {
    "x": 11,
    "y": 1,
    "z": 0,
    "block": "minecraft:stone"
  },
  {
    "x": 12,
    "y": 1,
    "z": 0,
    "block": "minecraft:stone"
  },
  {
    "x": 13,
    "y": 1,
    "z": 0,
    "block": "minecraft:stone"
  },
  {
    "x": 14,
    "y": 1,
    "z": 0,
    "block": "minecraft:stone"
  },
  {
    "x": 15,
    "y": 1,
    "z": 0,
    "block": "minecraft:stone"
  },
  {
    "x": 16,
    "y": 1,
    "z": 0,
    "block": "minecraft:stone"
  },
  {
    "x": 0,
    "y": 1,
    "z": 1,
    "block": "minecraft:stone"
  },
  {
    "x": 16,
    "y": 1,
    "z": 1,
    "block": "minecraft:stone"
  },
  {
    "x": 0,
    "y": 1,
    "z": 2,
    "block": "minecraft:stone"
  },
  {
    "x": 3,
    "y": 1,
    "z": 2,
    "block": "minecraft:stone"
  },
  {
    "x": 16,
    "y": 1,
    "z": 2,
    "block": "minecraft:stone"
  },
  {
    "x": 0,
    "y": 1,
    "z": 3,
    "block": "minecraft:stone"
  },
  {
    "x": 2,
    "y": 1,
    "z": 3,
    "block": "minecraft:stone"
  },
  {
    "x": 3,
    "y": 1,
    "z": 3,
    "block": "minecraft:sand"
  },
  {
    "x": 4,
    "y": 1,
    "z": 3,
    "block": "minecraft:stone"
  },
  {
    "x": 16,
    "y": 1,
    "z": 3,
    "block": "minecraft:stone"
  },
  {
    "x": 0,
    "y": 1,
    "z": 4,
    "block": "minecraft:stone"
  },
  {
    "x": 2,
    "y": 1,
    "z": 4,
    "block": "minecraft:stone"
  },
  {
    "x": 3,
    "y": 1,
    "z": 4,
    "block": "minecraft:packed_mud"
  },
  {
    "x": 4,
    "y": 1,
    "z": 4,
    "block": "minecraft:stone"
  },
  {
    "x": 5,
    "y": 1,
    "z": 4,
    "block": "minecraft:sand"
  },
  {
    "x": 16,
    "y": 1,
    "z": 4,
    "block": "minecraft:stone"
  },
  {
    "x": 0,
    "y": 1,
    "z": 5,
    "block": "minecraft:stone"
  },
  {
    "x": 1,
    "y": 1,
    "z": 5,
    "block": "minecraft:sand"
  },
  {
    "x": 2,
    "y": 1,
    "z": 5,
    "block": "minecraft:stone"
  },
  {
    "x": 3,
    "y": 1,
    "z": 5,
    "block": "minecraft:sand"
  },
  {
    "x": 4,
    "y": 1,
    "z": 5,
    "block": "minecraft:sand"
  },
  {
    "x": 5,
    "y": 1,
    "z": 5,
    "block": "minecraft:stone"
  },
  {
    "x": 6,
    "y": 1,
    "z": 5,
    "block": "minecraft:sand"
  },
  {
    "x": 16,
    "y": 1,
    "z": 5,
    "block": "minecraft:stone"
  },
  {
    "x": 0,
    "y": 1,
    "z": 6,
    "block": "minecraft:stone"
  },
  {
    "x": 2,
    "y": 1,
    "z": 6,
    "block": "minecraft:sand"
  },
  {
    "x": 3,
    "y": 1,
    "z": 6,
    "block": "minecraft:stone"
  },
  {
    "x": 4,
    "y": 1,
    "z": 6,
    "block": "minecraft:sand"
  },
  {
    "x": 5,
    "y": 1,
    "z": 6,
    "block": "minecraft:sand"
  },
  {
    "x": 6,
    "y": 1,
    "z": 6,
    "block": "minecraft:stone"
  },
  {
    "x": 16,
    "y": 1,
    "z": 6,
    "block": "minecraft:stone"
  },
  {
    "x": 0,
    "y": 1,
    "z": 7,
    "block": "minecraft:stone"
  },
  {
    "x": 3,
    "y": 1,
    "z": 7,
    "block": "minecraft:stone"
  },
  {
    "x": 4,
    "y": 1,
    "z": 7,
    "block": "minecraft:sand"
  },
  {
    "x": 5,
    "y": 1,
    "z": 7,
    "block": "minecraft:packed_mud"
  },
  {
    "x": 6,
    "y": 1,
    "z": 7,
    "block": "minecraft:stone"
  },
  {
    "x": 7,
    "y": 1,
    "z": 7,
    "block": "minecraft:sand"
  },
  {
    "x": 16,
    "y": 1,
    "z": 7,
    "block": "minecraft:stone"
  },
  {
    "x": 0,
    "y": 1,
    "z": 8,
    "block": "minecraft:stone"
  },
  {
    "x": 3,
    "y": 1,
    "z": 8,
    "block": "minecraft:stone"
  },
  {
    "x": 4,
    "y": 1,
    "z": 8,
    "block": "minecraft:packed_mud"
  },
  {
    "x": 5,
    "y": 1,
    "z": 8,
    "block": "minecraft:packed_mud"
  },
  {
    "x": 6,
    "y": 1,
    "z": 8,
    "block": "minecraft:stone"
  },
  {
    "x": 7,
    "y": 1,
    "z": 8,
    "block": "minecraft:sand"
  },
  {
    "x": 16,
    "y": 1,
    "z": 8,
    "block": "minecraft:stone"
  },
  {
    "x": 0,
    "y": 1,
    "z": 9,
    "block": "minecraft:stone"
  },
  {
    "x": 3,
    "y": 1,
    "z": 9,
    "block": "minecraft:stone"
  },
  {
    "x": 4,
    "y": 1,
    "z": 9,
    "block": "minecraft:packed_mud"
  },
  {
    "x": 5,
    "y": 1,
    "z": 9,
    "block": "minecraft:sand"
  },
  {
    "x": 6,
    "y": 1,
    "z": 9,
    "block": "minecraft:stone"
  },
  {
    "x": 7,
    "y": 1,
    "z": 9,
    "block": "minecraft:sand"
  },
  {
    "x": 16,
    "y": 1,
    "z": 9,
    "block": "minecraft:stone"
  },
  {
    "x": 0,
    "y": 1,
    "z": 10,
    "block": "minecraft:stone"
  },
  {
    "x": 2,
    "y": 1,
    "z": 10,
    "block": "minecraft:stone"
  },
  {
    "x": 3,
    "y": 1,
    "z": 10,
    "block": "minecraft:sand"
  },
  {
    "x": 4,
    "y": 1,
    "z": 10,
    "block": "minecraft:sand"
  },
  {
    "x": 5,
    "y": 1,
    "z": 10,
    "block": "minecraft:stone"
  },
  {
    "x": 6,
    "y": 1,
    "z": 10,
    "block": "minecraft:sand"
  },
  {
    "x": 16,
    "y": 1,
    "z": 10,
    "block": "minecraft:stone"
  },
  {
    "x": 0,
    "y": 1,
    "z": 11,
    "block": "minecraft:stone"
  },
  {
    "x": 1,
    "y": 1,
    "z": 11,
    "block": "minecraft:stone"
  },
  {
    "x": 2,
    "y": 1,
    "z": 11,
    "block": "minecraft:sand"
  },
  {
    "x": 3,
    "y": 1,
    "z": 11,
    "block": "minecraft:sand"
  },
  {
    "x": 4,
    "y": 1,
    "z": 11,
    "block": "minecraft:stone"
  },
  {
    "x": 5,
    "y": 1,
    "z": 11,
    "block": "minecraft:sand"
  },
  {
    "x": 6,
    "y": 1,
    "z": 11,
    "block": "minecraft:sand"
  },
  {
    "x": 16,
    "y": 1,
    "z": 11,
    "block": "minecraft:stone"
  },
  {
    "x": 0,
    "y": 1,
    "z": 12,
    "block": "minecraft:stone"
  },
  {
    "x": 1,
    "y": 1,
    "z": 12,
    "block": "minecraft:stone"
  },
  {
    "x": 2,
    "y": 1,
    "z": 12,
    "block": "minecraft:packed_mud"
  },
  {
    "x": 3,
    "y": 1,
    "z": 12,
    "block": "minecraft:stone"
  },
  {
    "x": 4,
    "y": 1,
    "z": 12,
    "block": "minecraft:sand"
  },
  {
    "x": 5,
    "y": 1,
    "z": 12,
    "block": "minecraft:sand"
  },
  {
    "x": 16,
    "y": 1,
    "z": 12,
    "block": "minecraft:stone"
  },
  {
    "x": 0,
    "y": 1,
    "z": 13,
    "block": "minecraft:stone"
  },
  {
    "x": 1,
    "y": 1,
    "z": 13,
    "block": "minecraft:stone"
  },
  {
    "x": 2,
    "y": 1,
    "z": 13,
    "block": "minecraft:packed_mud"
  },
  {
    "x": 3,
    "y": 1,
    "z": 13,
    "block": "minecraft:stone"
  },
  {
    "x": 4,
    "y": 1,
    "z": 13,
    "block": "minecraft:sand"
  },
  {
    "x": 16,
    "y": 1,
    "z": 13,
    "block": "minecraft:stone"
  },
  {
    "x": 0,
    "y": 1,
    "z": 14,
    "block": "minecraft:stone"
  },
  {
    "x": 1,
    "y": 1,
    "z": 14,
    "block": "minecraft:stone"
  },
  {
    "x": 2,
    "y": 1,
    "z": 14,
    "block": "minecraft:sand"
  },
  {
    "x": 3,
    "y": 1,
    "z": 14,
    "block": "minecraft:sand"
  },
  {
    "x": 4,
    "y": 1,
    "z": 14,
    "block": "minecraft:stone"
  },
  {
    "x": 5,
    "y": 1,
    "z": 14,
    "block": "minecraft:sand"
  },
  {
    "x": 16,
    "y": 1,
    "z": 14,
    "block": "minecraft:stone"
  },
  {
    "x": 0,
    "y": 1,
    "z": 15,
    "block": "minecraft:stone"
  },
  {
    "x": 1,
    "y": 1,
    "z": 15,
    "block": "minecraft:sand"
  },
  {
    "x": 2,
    "y": 1,
    "z": 15,
    "block": "minecraft:stone"
  },
  {
    "x": 3,
    "y": 1,
    "z": 15,
    "block": "minecraft:sand"
  },
  {
    "x": 4,
    "y": 1,
    "z": 15,
    "block": "minecraft:sand"
  },
  {
    "x": 5,
    "y": 1,
    "z": 15,
    "block": "minecraft:stone"
  },
  {
    "x": 16,
    "y": 1,
    "z": 15,
    "block": "minecraft:stone"
  },
  {
    "x": 0,
    "y": 1,
    "z": 16,
    "block": "minecraft:stone"
  },
  {
    "x": 1,
    "y": 1,
    "z": 16,
    "block": "minecraft:sand"
  },
  {
    "x": 2,
    "y": 1,
    "z": 16,
    "block": "minecraft:stone"
  },
  {
    "x": 3,
    "y": 1,
    "z": 16,
    "block": "minecraft:sand"
  },
  {
    "x": 4,
    "y": 1,
    "z": 16,
    "block": "minecraft:sand"
  },
  {
    "x": 5,
    "y": 1,
    "z": 16,
    "block": "minecraft:stone"
  },
  {
    "x": 6,
    "y": 1,
    "z": 16,
    "block": "minecraft:sand"
  },
  {
    "x": 16,
    "y": 1,
    "z": 16,
    "block": "minecraft:stone"
  },
  {
    "x": 0,
    "y": 1,
    "z": 17,
    "block": "minecraft:stone"
  },
  {
    "x": 2,
    "y": 1,
    "z": 17,
    "block": "minecraft:sand"
  },
  {
    "x": 3,
    "y": 1,
    "z": 17,
    "block": "minecraft:stone"
  },
  {
    "x": 4,
    "y": 1,
    "z": 17,
    "block": "minecraft:sand"
  },
  {
    "x": 5,
    "y": 1,
    "z": 17,
    "block": "minecraft:sand"
  },
  {
    "x": 6,
    "y": 1,
    "z": 17,
    "block": "minecraft:stone"
  },
  {
    "x": 16,
    "y": 1,
    "z": 17,
    "block": "minecraft:stone"
  },
  {
    "x": 0,
    "y": 1,
    "z": 18,
    "block": "minecraft:stone"
  },
  {
    "x": 2,
    "y": 1,
    "z": 18,
    "block": "minecraft:sand"
  },
  {
    "x": 3,
    "y": 1,
    "z": 18,
    "block": "minecraft:stone"
  },
  {
    "x": 4,
    "y": 1,
    "z": 18,
    "block": "minecraft:packed_mud"
  },
  {
    "x": 5,
    "y": 1,
    "z": 18,
    "block": "minecraft:packed_mud"
  },
  {
    "x": 6,
    "y": 1,
    "z": 18,
    "block": "minecraft:stone"
  },
  {
    "x": 16,
    "y": 1,
    "z": 18,
    "block": "minecraft:stone"
  },
  {
    "x": 0,
    "y": 1,
    "z": 19,
    "block": "minecraft:stone"
  },
  {
    "x": 2,
    "y": 1,
    "z": 19,
    "block": "minecraft:sand"
  },
  {
    "x": 3,
    "y": 1,
    "z": 19,
    "block": "minecraft:stone"
  },
  {
    "x": 4,
    "y": 1,
    "z": 19,
    "block": "minecraft:sand"
  },
  {
    "x": 5,
    "y": 1,
    "z": 19,
    "block": "minecraft:packed_mud"
  },
  {
    "x": 6,
    "y": 1,
    "z": 19,
    "block": "minecraft:stone"
  },
  {
    "x": 7,
    "y": 1,
    "z": 19,
    "block": "minecraft:sand"
  },
  {
    "x": 16,
    "y": 1,
    "z": 19,
    "block": "minecraft:stone"
  },
  {
    "x": 0,
    "y": 1,
    "z": 20,
    "block": "minecraft:stone"
  },
  {
    "x": 3,
    "y": 1,
    "z": 20,
    "block": "minecraft:stone"
  },
  {
    "x": 4,
    "y": 1,
    "z": 20,
    "block": "minecraft:packed_mud"
  },
  {
    "x": 5,
    "y": 1,
    "z": 20,
    "block": "minecraft:packed_mud"
  },
  {
    "x": 6,
    "y": 1,
    "z": 20,
    "block": "minecraft:stone"
  },
  {
    "x": 7,
    "y": 1,
    "z": 20,
    "block": "minecraft:sand"
  },
  {
    "x": 16,
    "y": 1,
    "z": 20,
    "block": "minecraft:stone"
  },
  {
    "x": 0,
    "y": 1,
    "z": 21,
    "block": "minecraft:stone"
  },
  {
    "x": 3,
    "y": 1,
    "z": 21,
    "block": "minecraft:stone"
  },
  {
    "x": 4,
    "y": 1,
    "z": 21,
    "block": "minecraft:sand"
  },
  {
    "x": 5,
    "y": 1,
    "z": 21,
    "block": "minecraft:sand"
  },
  {
    "x": 6,
    "y": 1,
    "z": 21,
    "block": "minecraft:sand"
  },
  {
    "x": 7,
    "y": 1,
    "z": 21,
    "block": "minecraft:stone"
  },
  {
    "x": 16,
    "y": 1,
    "z": 21,
    "block": "minecraft:stone"
  },
  {
    "x": 0,
    "y": 1,
    "z": 22,
    "block": "minecraft:stone"
  },
  {
    "x": 3,
    "y": 1,
    "z": 22,
    "block": "minecraft:sand"
  },
  {
    "x": 4,
    "y": 1,
    "z": 22,
    "block": "minecraft:stone"
  },
  {
    "x": 5,
    "y": 1,
    "z": 22,
    "block": "minecraft:sand"
  },
  {
    "x": 6,
    "y": 1,
    "z": 22,
    "block": "minecraft:sand"
  },
  {
    "x": 7,
    "y": 1,
    "z": 22,
    "block": "minecraft:stone"
  },
  {
    "x": 16,
    "y": 1,
    "z": 22,
    "block": "minecraft:stone"
  },
  {
    "x": 0,
    "y": 1,
    "z": 23,
    "block": "minecraft:stone"
  },
  {
    "x": 3,
    "y": 1,
    "z": 23,
    "block": "minecraft:sand"
  },
  {
    "x": 4,
    "y": 1,
    "z": 23,
    "block": "minecraft:stone"
  },
  {
    "x": 5,
    "y": 1,
    "z": 23,
    "block": "minecraft:sand"
  },
  {
    "x": 6,
    "y": 1,
    "z": 23,
    "block": "minecraft:sand"
  },
  {
    "x": 7,
    "y": 1,
    "z": 23,
    "block": "minecraft:stone"
  },
  {
    "x": 8,
    "y": 1,
    "z": 23,
    "block": "minecraft:sand"
  },
  {
    "x": 16,
    "y": 1,
    "z": 23,
    "block": "minecraft:stone"
  },
  {
    "x": 0,
    "y": 1,
    "z": 24,
    "block": "minecraft:stone"
  },
  {
    "x": 4,
    "y": 1,
    "z": 24,
    "block": "minecraft:stone"
  },
  {
    "x": 5,
    "y": 1,
    "z": 24,
    "block": "minecraft:sand"
  },
  {
    "x": 6,
    "y": 1,
    "z": 24,
    "block": "minecraft:sand"
  },
  {
    "x": 7,
    "y": 1,
    "z": 24,
    "block": "minecraft:sand"
  },
  {
    "x": 8,
    "y": 1,
    "z": 24,
    "block": "minecraft:stone"
  },
  {
    "x": 16,
    "y": 1,
    "z": 24,
    "block": "minecraft:stone"
  },
  {
    "x": 0,
    "y": 1,
    "z": 25,
    "block": "minecraft:stone"
  },
  {
    "x": 4,
    "y": 1,
    "z": 25,
    "block": "minecraft:stone"
  },
  {
    "x": 5,
    "y": 1,
    "z": 25,
    "block": "minecraft:sand"
  },
  {
    "x": 6,
    "y": 1,
    "z": 25,
    "block": "minecraft:sand"
  },
  {
    "x": 7,
    "y": 1,
    "z": 25,
    "block": "minecraft:sand"
  },
  {
    "x": 8,
    "y": 1,
    "z": 25,
    "block": "minecraft:stone"
  },
  {
    "x": 16,
    "y": 1,
    "z": 25,
    "block": "minecraft:stone"
  },
  {
    "x": 0,
    "y": 1,
    "z": 26,
    "block": "minecraft:stone"
  },
  {
    "x": 5,
    "y": 1,
    "z": 26,
    "block": "minecraft:stone"
  },
  {
    "x": 6,
    "y": 1,
    "z": 26,
    "block": "minecraft:packed_mud"
  },
  {
    "x": 7,
    "y": 1,
    "z": 26,
    "block": "minecraft:sand"
  },
  {
    "x": 8,
    "y": 1,
    "z": 26,
    "block": "minecraft:stone"
  },
  {
    "x": 9,
    "y": 1,
    "z": 26,
    "block": "minecraft:sand"
  },
  {
    "x": 16,
    "y": 1,
    "z": 26,
    "block": "minecraft:stone"
  },
  {
    "x": 0,
    "y": 1,
    "z": 27,
    "block": "minecraft:stone"
  },
  {
    "x": 5,
    "y": 1,
    "z": 27,
    "block": "minecraft:stone"
  },
  {
    "x": 6,
    "y": 1,
    "z": 27,
    "block": "minecraft:sand"
  },
  {
    "x": 7,
    "y": 1,
    "z": 27,
    "block": "minecraft:sand"
  },
  {
    "x": 8,
    "y": 1,
    "z": 27,
    "block": "minecraft:sand"
  },
  {
    "x": 9,
    "y": 1,
    "z": 27,
    "block": "minecraft:stone"
  },
  {
    "x": 10,
    "y": 1,
    "z": 27,
    "block": "minecraft:sand"
  },
  {
    "x": 16,
    "y": 1,
    "z": 27,
    "block": "minecraft:stone"
  },
  {
    "x": 0,
    "y": 1,
    "z": 28,
    "block": "minecraft:stone"
  },
  {
    "x": 6,
    "y": 1,
    "z": 28,
    "block": "minecraft:stone"
  },
  {
    "x": 7,
    "y": 1,
    "z": 28,
    "block": "minecraft:packed_mud"
  },
  {
    "x": 8,
    "y": 1,
    "z": 28,
    "block": "minecraft:sand"
  },
  {
    "x": 9,
    "y": 1,
    "z": 28,
    "block": "minecraft:sand"
  },
  {
    "x": 10,
    "y": 1,
    "z": 28,
    "block": "minecraft:stone"
  },
  {
    "x": 16,
    "y": 1,
    "z": 28,
    "block": "minecraft:stone"
  },
  {
    "x": 0,
    "y": 1,
    "z": 29,
    "block": "minecraft:stone"
  },
  {
    "x": 6,
    "y": 1,
    "z": 29,
    "block": "minecraft:stone"
  },
  {
    "x": 7,
    "y": 1,
    "z": 29,
    "block": "minecraft:packed_mud"
  },
  {
    "x": 8,
    "y": 1,
    "z": 29,
    "block": "minecraft:packed_mud"
  },
  {
    "x": 9,
    "y": 1,
    "z": 29,
    "block": "minecraft:packed_mud"
  },
  {
    "x": 10,
    "y": 1,
    "z": 29,
    "block": "minecraft:stone"
  },
  {
    "x": 11,
    "y": 1,
    "z": 29,
    "block": "minecraft:sand"
  },
  {
    "x": 16,
    "y": 1,
    "z": 29,
    "block": "minecraft:stone"
  },
  {
    "x": 0,
    "y": 1,
    "z": 30,
    "block": "minecraft:stone"
  },
  {
    "x": 6,
    "y": 1,
    "z": 30,
    "block": "minecraft:stone"
  },
  {
    "x": 7,
    "y": 1,
    "z": 30,
    "block": "minecraft:sand"
  },
  {
    "x": 8,
    "y": 1,
    "z": 30,
    "block": "minecraft:packed_mud"
  },
  {
    "x": 9,
    "y": 1,
    "z": 30,
    "block": "minecraft:packed_mud"
  },
  {
    "x": 10,
    "y": 1,
    "z": 30,
    "block": "minecraft:packed_mud"
  },
  {
    "x": 11,
    "y": 1,
    "z": 30,
    "block": "minecraft:stone"
  },
  {
    "x": 16,
    "y": 1,
    "z": 30,
    "block": "minecraft:stone"
  },
  {
    "x": 0,
    "y": 1,
    "z": 31,
    "block": "minecraft:stone"
  },
  {
    "x": 7,
    "y": 1,
    "z": 31,
    "block": "minecraft:stone"
  },
  {
    "x": 8,
    "y": 1,
    "z": 31,
    "block": "minecraft:sand"
  },
  {
    "x": 9,
    "y": 1,
    "z": 31,
    "block": "minecraft:sand"
  },
  {
    "x": 10,
    "y": 1,
    "z": 31,
    "block": "minecraft:sand"
  },
  {
    "x": 11,
    "y": 1,
    "z": 31,
    "block": "minecraft:stone"
  },
  {
    "x": 12,
    "y": 1,
    "z": 31,
    "block": "minecraft:sand"
  },
  {
    "x": 16,
    "y": 1,
    "z": 31,
    "block": "minecraft:stone"
  },
  {
    "x": 0,
    "y": 1,
    "z": 32,
    "block": "minecraft:stone"
  },
  {
    "x": 8,
    "y": 1,
    "z": 32,
    "block": "minecraft:stone"
  },
  {
    "x": 9,
    "y": 1,
    "z": 32,
    "block": "minecraft:sand"
  },
  {
    "x": 10,
    "y": 1,
    "z": 32,
    "block": "minecraft:sand"
  },
  {
    "x": 11,
    "y": 1,
    "z": 32,
    "block": "minecraft:sand"
  },
  {
    "x": 12,
    "y": 1,
    "z": 32,
    "block": "minecraft:stone"
  },
  {
    "x": 13,
    "y": 1,
    "z": 32,
    "block": "minecraft:sand"
  },
  {
    "x": 16,
    "y": 1,
    "z": 32,
    "block": "minecraft:stone"
  },
  {
    "x": 0,
    "y": 1,
    "z": 33,
    "block": "minecraft:stone"
  },
  {
    "x": 1,
    "y": 1,
    "z": 33,
    "block": "minecraft:stone"
  },
  {
    "x": 2,
    "y": 1,
    "z": 33,
    "block": "minecraft:stone"
  },
  {
    "x": 3,
    "y": 1,
    "z": 33,
    "block": "minecraft:stone"
  },
  {
    "x": 4,
    "y": 1,
    "z": 33,
    "block": "minecraft:stone"
  },
  {
    "x": 5,
    "y": 1,
    "z": 33,
    "block": "minecraft:stone"
  },
  {
    "x": 6,
    "y": 1,
    "z": 33,
    "block": "minecraft:stone"
  },
  {
    "x": 7,
    "y": 1,
    "z": 33,
    "block": "minecraft:stone"
  },
  {
    "x": 8,
    "y": 1,
    "z": 33,
    "block": "minecraft:stone"
  },
  {
    "x": 9,
    "y": 1,
    "z": 33,
    "block": "minecraft:blue_stained_glass"
  },
  {
    "x": 10,
    "y": 1,
    "z": 33,
    "block": "minecraft:blue_stained_glass"
  },
  {
    "x": 11,
    "y": 1,
    "z": 33,
    "block": "minecraft:blue_stained_glass"
  },
  {
    "x": 12,
    "y": 1,
    "z": 33,
    "block": "minecraft:stone"
  },
  {
    "x": 13,
    "y": 1,
    "z": 33,
    "block": "minecraft:stone"
  },
  {
    "x": 14,
    "y": 1,
    "z": 33,
    "block": "minecraft:stone"
  },
  {
    "x": 15,
    "y": 1,
    "z": 33,
    "block": "minecraft:stone"
  },
  {
    "x": 16,
    "y": 1,
    "z": 33,
    "block": "minecraft:stone"
  },
  {
    "x": 0,
    "y": 2,
    "z": 0,
    "block": "minecraft:red_terracotta"
  },
  {
    "x": 1,
    "y": 2,
    "z": 0,
    "block": "minecraft:red_terracotta"
  },
  {
    "x": 2,
    "y": 2,
    "z": 0,
    "block": "minecraft:red_terracotta"
  },
  {
    "x": 3,
    "y": 2,
    "z": 0,
    "block": "minecraft:red_terracotta"
  },
  {
    "x": 4,
    "y": 2,
    "z": 0,
    "block": "minecraft:red_terracotta"
  },
  {
    "x": 5,
    "y": 2,
    "z": 0,
    "block": "minecraft:red_terracotta"
  },
  {
    "x": 6,
    "y": 2,
    "z": 0,
    "block": "minecraft:red_terracotta"
  },
  {
    "x": 7,
    "y": 2,
    "z": 0,
    "block": "minecraft:red_terracotta"
  },
  {
    "x": 8,
    "y": 2,
    "z": 0,
    "block": "minecraft:red_terracotta"
  },
  {
    "x": 9,
    "y": 2,
    "z": 0,
    "block": "minecraft:red_terracotta"
  },
  {
    "x": 10,
    "y": 2,
    "z": 0,
    "block": "minecraft:red_terracotta"
  },
  {
    "x": 11,
    "y": 2,
    "z": 0,
    "block": "minecraft:red_terracotta"
  },
  {
    "x": 12,
    "y": 2,
    "z": 0,
    "block": "minecraft:red_terracotta"
  },
  {
    "x": 13,
    "y": 2,
    "z": 0,
    "block": "minecraft:red_terracotta"
  },
  {
    "x": 14,
    "y": 2,
    "z": 0,
    "block": "minecraft:red_terracotta"
  },
  {
    "x": 15,
    "y": 2,
    "z": 0,
    "block": "minecraft:red_terracotta"
  },
  {
    "x": 16,
    "y": 2,
    "z": 0,
    "block": "minecraft:red_terracotta"
  },
  {
    "x": 0,
    "y": 2,
    "z": 1,
    "block": "minecraft:red_terracotta"
  },
  {
    "x": 1,
    "y": 2,
    "z": 1,
    "block": "minecraft:dirt"
  },
  {
    "x": 2,
    "y": 2,
    "z": 1,
    "block": "minecraft:dirt"
  },
  {
    "x": 3,
    "y": 2,
    "z": 1,
    "block": "minecraft:dirt"
  },
  {
    "x": 4,
    "y": 2,
    "z": 1,
    "block": "minecraft:dirt"
  },
  {
    "x": 5,
    "y": 2,
    "z": 1,
    "block": "minecraft:grass_block[snowy=false]"
  },
  {
    "x": 6,
    "y": 2,
    "z": 1,
    "block": "minecraft:grass_block[snowy=false]"
  },
  {
    "x": 7,
    "y": 2,
    "z": 1,
    "block": "minecraft:grass_block[snowy=false]"
  },
  {
    "x": 8,
    "y": 2,
    "z": 1,
    "block": "minecraft:grass_block[snowy=false]"
  },
  {
    "x": 9,
    "y": 2,
    "z": 1,
    "block": "minecraft:grass_block[snowy=false]"
  },
  {
    "x": 10,
    "y": 2,
    "z": 1,
    "block": "minecraft:grass_block[snowy=false]"
  },
  {
    "x": 11,
    "y": 2,
    "z": 1,
    "block": "minecraft:grass_block[snowy=false]"
  },
  {
    "x": 12,
    "y": 2,
    "z": 1,
    "block": "minecraft:grass_block[snowy=false]"
  },
  {
    "x": 13,
    "y": 2,
    "z": 1,
    "block": "minecraft:grass_block[snowy=false]"
  },
  {
    "x": 14,
    "y": 2,
    "z": 1,
    "block": "minecraft:grass_block[snowy=false]"
  },
  {
    "x": 15,
    "y": 2,
    "z": 1,
    "block": "minecraft:grass_block[snowy=false]"
  },
  {
    "x": 16,
    "y": 2,
    "z": 1,
    "block": "minecraft:red_terracotta"
  },
  {
    "x": 0,
    "y": 2,
    "z": 2,
    "block": "minecraft:red_terracotta"
  },
  {
    "x": 1,
    "y": 2,
    "z": 2,
    "block": "minecraft:dirt"
  },
  {
    "x": 2,
    "y": 2,
    "z": 2,
    "block": "minecraft:dirt"
  },
  {
    "x": 3,
    "y": 2,
    "z": 2,
    "block": "minecraft:dirt"
  },
  {
    "x": 4,
    "y": 2,
    "z": 2,
    "block": "minecraft:dirt"
  },
  {
    "x": 5,
    "y": 2,
    "z": 2,
    "block": "minecraft:grass_block[snowy=false]"
  },
  {
    "x": 6,
    "y": 2,
    "z": 2,
    "block": "minecraft:grass_block[snowy=false]"
  },
  {
    "x": 7,
    "y": 2,
    "z": 2,
    "block": "minecraft:grass_block[snowy=false]"
  },
  {
    "x": 8,
    "y": 2,
    "z": 2,
    "block": "minecraft:grass_block[snowy=false]"
  },
  {
    "x": 9,
    "y": 2,
    "z": 2,
    "block": "minecraft:grass_block[snowy=false]"
  },
  {
    "x": 10,
    "y": 2,
    "z": 2,
    "block": "minecraft:grass_block[snowy=false]"
  },
  {
    "x": 11,
    "y": 2,
    "z": 2,
    "block": "minecraft:grass_block[snowy=false]"
  },
  {
    "x": 12,
    "y": 2,
    "z": 2,
    "block": "minecraft:grass_block[snowy=false]"
  },
  {
    "x": 13,
    "y": 2,
    "z": 2,
    "block": "minecraft:grass_block[snowy=false]"
  },
  {
    "x": 14,
    "y": 2,
    "z": 2,
    "block": "minecraft:grass_block[snowy=false]"
  },
  {
    "x": 15,
    "y": 2,
    "z": 2,
    "block": "minecraft:grass_block[snowy=false]"
  },
  {
    "x": 16,
    "y": 2,
    "z": 2,
    "block": "minecraft:red_terracotta"
  },
  {
    "x": 0,
    "y": 2,
    "z": 3,
    "block": "minecraft:red_terracotta"
  },
  {
    "x": 1,
    "y": 2,
    "z": 3,
    "block": "minecraft:dirt"
  },
  {
    "x": 2,
    "y": 2,
    "z": 3,
    "block": "minecraft:dirt"
  },
  {
    "x": 3,
    "y": 2,
    "z": 3,
    "block": "minecraft:sand"
  },
  {
    "x": 4,
    "y": 2,
    "z": 3,
    "block": "minecraft:sand"
  },
  {
    "x": 5,
    "y": 2,
    "z": 3,
    "block": "minecraft:grass_block[snowy=false]"
  },
  {
    "x": 6,
    "y": 2,
    "z": 3,
    "block": "minecraft:grass_block[snowy=false]"
  },
  {
    "x": 7,
    "y": 2,
    "z": 3,
    "block": "minecraft:grass_block[snowy=false]"
  },
  {
    "x": 8,
    "y": 2,
    "z": 3,
    "block": "minecraft:grass_block[snowy=false]"
  },
  {
    "x": 9,
    "y": 2,
    "z": 3,
    "block": "minecraft:grass_block[snowy=false]"
  },
  {
    "x": 10,
    "y": 2,
    "z": 3,
    "block": "minecraft:grass_block[snowy=false]"
  },
  {
    "x": 11,
    "y": 2,
    "z": 3,
    "block": "minecraft:grass_block[snowy=false]"
  },
  {
    "x": 12,
    "y": 2,
    "z": 3,
    "block": "minecraft:grass_block[snowy=false]"
  },
  {
    "x": 13,
    "y": 2,
    "z": 3,
    "block": "minecraft:grass_block[snowy=false]"
  },
  {
    "x": 14,
    "y": 2,
    "z": 3,
    "block": "minecraft:grass_block[snowy=false]"
  },
  {
    "x": 15,
    "y": 2,
    "z": 3,
    "block": "minecraft:grass_block[snowy=false]"
  },
  {
    "x": 16,
    "y": 2,
    "z": 3,
    "block": "minecraft:red_terracotta"
  },
  {
    "x": 0,
    "y": 2,
    "z": 4,
    "block": "minecraft:red_terracotta"
  },
  {
    "x": 1,
    "y": 2,
    "z": 4,
    "block": "minecraft:dirt"
  },
  {
    "x": 2,
    "y": 2,
    "z": 4,
    "block": "minecraft:sand"
  },
  {
    "x": 3,
    "y": 2,
    "z": 4,
    "block": "minecraft:blue_stained_glass"
  },
  {
    "x": 4,
    "y": 2,
    "z": 4,
    "block": "minecraft:sand"
  },
  {
    "x": 5,
    "y": 2,
    "z": 4,
    "block": "minecraft:sand"
  },
  {
    "x": 6,
    "y": 2,
    "z": 4,
    "block": "minecraft:grass_block[snowy=false]"
  },
  {
    "x": 7,
    "y": 2,
    "z": 4,
    "block": "minecraft:grass_block[snowy=false]"
  },
  {
    "x": 8,
    "y": 2,
    "z": 4,
    "block": "minecraft:grass_block[snowy=false]"
  },
  {
    "x": 9,
    "y": 2,
    "z": 4,
    "block": "minecraft:grass_block[snowy=false]"
  },
  {
    "x": 10,
    "y": 2,
    "z": 4,
    "block": "minecraft:grass_block[snowy=false]"
  },
  {
    "x": 11,
    "y": 2,
    "z": 4,
    "block": "minecraft:grass_block[snowy=false]"
  },
  {
    "x": 12,
    "y": 2,
    "z": 4,
    "block": "minecraft:grass_block[snowy=false]"
  },
  {
    "x": 13,
    "y": 2,
    "z": 4,
    "block": "minecraft:grass_block[snowy=false]"
  },
  {
    "x": 14,
    "y": 2,
    "z": 4,
    "block": "minecraft:grass_block[snowy=false]"
  },
  {
    "x": 15,
    "y": 2,
    "z": 4,
    "block": "minecraft:grass_block[snowy=false]"
  },
  {
    "x": 16,
    "y": 2,
    "z": 4,
    "block": "minecraft:red_terracotta"
  },
  {
    "x": 0,
    "y": 2,
    "z": 5,
    "block": "minecraft:red_terracotta"
  },
  {
    "x": 1,
    "y": 2,
    "z": 5,
    "block": "minecraft:sand"
  },
  {
    "x": 2,
    "y": 2,
    "z": 5,
    "block": "minecraft:sand"
  },
  {
    "x": 3,
    "y": 2,
    "z": 5,
    "block": "minecraft:blue_stained_glass"
  },
  {
    "x": 4,
    "y": 2,
    "z": 5,
    "block": "minecraft:blue_stained_glass"
  },
  {
    "x": 5,
    "y": 2,
    "z": 5,
    "block": "minecraft:sand"
  },
  {
    "x": 6,
    "y": 2,
    "z": 5,
    "block": "minecraft:sand"
  },
  {
    "x": 7,
    "y": 2,
    "z": 5,
    "block": "minecraft:grass_block[snowy=false]"
  },
  {
    "x": 8,
    "y": 2,
    "z": 5,
    "block": "minecraft:grass_block[snowy=false]"
  },
  {
    "x": 9,
    "y": 2,
    "z": 5,
    "block": "minecraft:grass_block[snowy=false]"
  },
  {
    "x": 10,
    "y": 2,
    "z": 5,
    "block": "minecraft:grass_block[snowy=false]"
  },
  {
    "x": 11,
    "y": 2,
    "z": 5,
    "block": "minecraft:grass_block[snowy=false]"
  },
  {
    "x": 12,
    "y": 2,
    "z": 5,
    "block": "minecraft:grass_block[snowy=false]"
  },
  {
    "x": 13,
    "y": 2,
    "z": 5,
    "block": "minecraft:grass_block[snowy=false]"
  },
  {
    "x": 14,
    "y": 2,
    "z": 5,
    "block": "minecraft:grass_block[snowy=false]"
  },
  {
    "x": 15,
    "y": 2,
    "z": 5,
    "block": "minecraft:grass_block[snowy=false]"
  },
  {
    "x": 16,
    "y": 2,
    "z": 5,
    "block": "minecraft:red_terracotta"
  },
  {
    "x": 0,
    "y": 2,
    "z": 6,
    "block": "minecraft:red_terracotta"
  },
  {
    "x": 1,
    "y": 2,
    "z": 6,
    "block": "minecraft:grass_block[snowy=false]"
  },
  {
    "x": 2,
    "y": 2,
    "z": 6,
    "block": "minecraft:sand"
  },
  {
    "x": 3,
    "y": 2,
    "z": 6,
    "block": "minecraft:packed_mud"
  },
  {
    "x": 4,
    "y": 2,
    "z": 6,
    "block": "minecraft:blue_stained_glass"
  },
  {
    "x": 5,
    "y": 2,
    "z": 6,
    "block": "minecraft:blue_stained_glass"
  },
  {
    "x": 6,
    "y": 2,
    "z": 6,
    "block": "minecraft:sand"
  },
  {
    "x": 7,
    "y": 2,
    "z": 6,
    "block": "minecraft:grass_block[snowy=false]"
  },
  {
    "x": 8,
    "y": 2,
    "z": 6,
    "block": "minecraft:grass_block[snowy=false]"
  },
  {
    "x": 9,
    "y": 2,
    "z": 6,
    "block": "minecraft:grass_block[snowy=false]"
  },
  {
    "x": 10,
    "y": 2,
    "z": 6,
    "block": "minecraft:grass_block[snowy=false]"
  },
  {
    "x": 11,
    "y": 2,
    "z": 6,
    "block": "minecraft:grass_block[snowy=false]"
  },
  {
    "x": 12,
    "y": 2,
    "z": 6,
    "block": "minecraft:grass_block[snowy=false]"
  },
  {
    "x": 13,
    "y": 2,
    "z": 6,
    "block": "minecraft:grass_block[snowy=false]"
  },
  {
    "x": 14,
    "y": 2,
    "z": 6,
    "block": "minecraft:grass_block[snowy=false]"
  },
  {
    "x": 15,
    "y": 2,
    "z": 6,
    "block": "minecraft:grass_block[snowy=false]"
  },
  {
    "x": 16,
    "y": 2,
    "z": 6,
    "block": "minecraft:red_terracotta"
  },
  {
    "x": 0,
    "y": 2,
    "z": 7,
    "block": "minecraft:red_terracotta"
  },
  {
    "x": 1,
    "y": 2,
    "z": 7,
    "block": "minecraft:grass_block[snowy=false]"
  },
  {
    "x": 2,
    "y": 2,
    "z": 7,
    "block": "minecraft:grass_block[snowy=false]"
  },
  {
    "x": 3,
    "y": 2,
    "z": 7,
    "block": "minecraft:sand"
  },
  {
    "x": 4,
    "y": 2,
    "z": 7,
    "block": "minecraft:blue_stained_glass"
  },
  {
    "x": 5,
    "y": 2,
    "z": 7,
    "block": "minecraft:blue_stained_glass"
  },
  {
    "x": 6,
    "y": 2,
    "z": 7,
    "block": "minecraft:packed_mud"
  },
  {
    "x": 7,
    "y": 2,
    "z": 7,
    "block": "minecraft:sand"
  },
  {
    "x": 8,
    "y": 2,
    "z": 7,
    "block": "minecraft:grass_block[snowy=false]"
  },
  {
    "x": 9,
    "y": 2,
    "z": 7,
    "block": "minecraft:grass_block[snowy=false]"
  },
  {
    "x": 10,
    "y": 2,
    "z": 7,
    "block": "minecraft:grass_block[snowy=false]"
  },
  {
    "x": 11,
    "y": 2,
    "z": 7,
    "block": "minecraft:grass_block[snowy=false]"
  },
  {
    "x": 12,
    "y": 2,
    "z": 7,
    "block": "minecraft:grass_block[snowy=false]"
  },
  {
    "x": 13,
    "y": 2,
    "z": 7,
    "block": "minecraft:grass_block[snowy=false]"
  },
  {
    "x": 14,
    "y": 2,
    "z": 7,
    "block": "minecraft:grass_block[snowy=false]"
  },
  {
    "x": 15,
    "y": 2,
    "z": 7,
    "block": "minecraft:dirt"
  },
  {
    "x": 16,
    "y": 2,
    "z": 7,
    "block": "minecraft:red_terracotta"
  },
  {
    "x": 0,
    "y": 2,
    "z": 8,
    "block": "minecraft:red_terracotta"
  },
  {
    "x": 1,
    "y": 2,
    "z": 8,
    "block": "minecraft:grass_block[snowy=false]"
  },
  {
    "x": 2,
    "y": 2,
    "z": 8,
    "block": "minecraft:grass_block[snowy=false]"
  },
  {
    "x": 3,
    "y": 2,
    "z": 8,
    "block": "minecraft:sand"
  },
  {
    "x": 4,
    "y": 2,
    "z": 8,
    "block": "minecraft:blue_stained_glass"
  },
  {
    "x": 5,
    "y": 2,
    "z": 8,
    "block": "minecraft:blue_stained_glass"
  },
  {
    "x": 6,
    "y": 2,
    "z": 8,
    "block": "minecraft:packed_mud"
  },
  {
    "x": 7,
    "y": 2,
    "z": 8,
    "block": "minecraft:sand"
  },
  {
    "x": 8,
    "y": 2,
    "z": 8,
    "block": "minecraft:grass_block[snowy=false]"
  },
  {
    "x": 9,
    "y": 2,
    "z": 8,
    "block": "minecraft:grass_block[snowy=false]"
  },
  {
    "x": 10,
    "y": 2,
    "z": 8,
    "block": "minecraft:grass_block[snowy=false]"
  },
  {
    "x": 11,
    "y": 2,
    "z": 8,
    "block": "minecraft:grass_block[snowy=false]"
  },
  {
    "x": 12,
    "y": 2,
    "z": 8,
    "block": "minecraft:dirt"
  },
  {
    "x": 13,
    "y": 2,
    "z": 8,
    "block": "minecraft:dirt"
  },
  {
    "x": 14,
    "y": 2,
    "z": 8,
    "block": "minecraft:dirt"
  },
  {
    "x": 15,
    "y": 2,
    "z": 8,
    "block": "minecraft:dirt"
  },
  {
    "x": 16,
    "y": 2,
    "z": 8,
    "block": "minecraft:red_terracotta"
  },
  {
    "x": 0,
    "y": 2,
    "z": 9,
    "block": "minecraft:red_terracotta"
  },
  {
    "x": 1,
    "y": 2,
    "z": 9,
    "block": "minecraft:grass_block[snowy=false]"
  },
  {
    "x": 2,
    "y": 2,
    "z": 9,
    "block": "minecraft:grass_block[snowy=false]"
  },
  {
    "x": 3,
    "y": 2,
    "z": 9,
    "block": "minecraft:sand"
  },
  {
    "x": 4,
    "y": 2,
    "z": 9,
    "block": "minecraft:blue_stained_glass"
  },
  {
    "x": 5,
    "y": 2,
    "z": 9,
    "block": "minecraft:blue_stained_glass"
  },
  {
    "x": 6,
    "y": 2,
    "z": 9,
    "block": "minecraft:sand"
  },
  {
    "x": 7,
    "y": 2,
    "z": 9,
    "block": "minecraft:sand"
  },
  {
    "x": 8,
    "y": 2,
    "z": 9,
    "block": "minecraft:grass_block[snowy=false]"
  },
  {
    "x": 9,
    "y": 2,
    "z": 9,
    "block": "minecraft:grass_block[snowy=false]"
  },
  {
    "x": 10,
    "y": 2,
    "z": 9,
    "block": "minecraft:grass_block[snowy=false]"
  },
  {
    "x": 11,
    "y": 2,
    "z": 9,
    "block": "minecraft:dirt"
  },
  {
    "x": 12,
    "y": 2,
    "z": 9,
    "block": "minecraft:dirt"
  },
  {
    "x": 13,
    "y": 2,
    "z": 9,
    "block": "minecraft:dirt"
  },
  {
    "x": 14,
    "y": 2,
    "z": 9,
    "block": "minecraft:dirt"
  },
  {
    "x": 15,
    "y": 2,
    "z": 9,
    "block": "minecraft:dirt"
  },
  {
    "x": 16,
    "y": 2,
    "z": 9,
    "block": "minecraft:red_terracotta"
  },
  {
    "x": 0,
    "y": 2,
    "z": 10,
    "block": "minecraft:red_terracotta"
  },
  {
    "x": 1,
    "y": 2,
    "z": 10,
    "block": "minecraft:grass_block[snowy=false]"
  },
  {
    "x": 2,
    "y": 2,
    "z": 10,
    "block": "minecraft:sand"
  },
  {
    "x": 3,
    "y": 2,
    "z": 10,
    "block": "minecraft:blue_stained_glass"
  },
  {
    "x": 4,
    "y": 2,
    "z": 10,
    "block": "minecraft:blue_stained_glass"
  },
  {
    "x": 5,
    "y": 2,
    "z": 10,
    "block": "minecraft:sand"
  },
  {
    "x": 6,
    "y": 2,
    "z": 10,
    "block": "minecraft:sand"
  },
  {
    "x": 7,
    "y": 2,
    "z": 10,
    "block": "minecraft:grass_block[snowy=false]"
  },
  {
    "x": 8,
    "y": 2,
    "z": 10,
    "block": "minecraft:grass_block[snowy=false]"
  },
  {
    "x": 9,
    "y": 2,
    "z": 10,
    "block": "minecraft:grass_block[snowy=false]"
  },
  {
    "x": 10,
    "y": 2,
    "z": 10,
    "block": "minecraft:dirt"
  },
  {
    "x": 11,
    "y": 2,
    "z": 10,
    "block": "minecraft:dirt"
  },
  {
    "x": 12,
    "y": 2,
    "z": 10,
    "block": "minecraft:dirt"
  },
  {
    "x": 13,
    "y": 2,
    "z": 10,
    "block": "minecraft:dirt"
  },
  {
    "x": 14,
    "y": 2,
    "z": 10,
    "block": "minecraft:dirt"
  },
  {
    "x": 15,
    "y": 2,
    "z": 10,
    "block": "minecraft:dirt"
  },
  {
    "x": 16,
    "y": 2,
    "z": 10,
    "block": "minecraft:red_terracotta"
  },
  {
    "x": 0,
    "y": 2,
    "z": 11,
    "block": "minecraft:red_terracotta"
  },
  {
    "x": 1,
    "y": 2,
    "z": 11,
    "block": "minecraft:sand"
  },
  {
    "x": 2,
    "y": 2,
    "z": 11,
    "block": "minecraft:blue_stained_glass"
  },
  {
    "x": 3,
    "y": 2,
    "z": 11,
    "block": "minecraft:blue_stained_glass"
  },
  {
    "x": 4,
    "y": 2,
    "z": 11,
    "block": "minecraft:sand"
  },
  {
    "x": 5,
    "y": 2,
    "z": 11,
    "block": "minecraft:sand"
  },
  {
    "x": 6,
    "y": 2,
    "z": 11,
    "block": "minecraft:sand"
  },
  {
    "x": 7,
    "y": 2,
    "z": 11,
    "block": "minecraft:grass_block[snowy=false]"
  },
  {
    "x": 8,
    "y": 2,
    "z": 11,
    "block": "minecraft:grass_block[snowy=false]"
  },
  {
    "x": 9,
    "y": 2,
    "z": 11,
    "block": "minecraft:grass_block[snowy=false]"
  },
  {
    "x": 10,
    "y": 2,
    "z": 11,
    "block": "minecraft:dirt"
  },
  {
    "x": 11,
    "y": 2,
    "z": 11,
    "block": "minecraft:dirt"
  },
  {
    "x": 12,
    "y": 2,
    "z": 11,
    "block": "minecraft:dirt"
  },
  {
    "x": 13,
    "y": 2,
    "z": 11,
    "block": "minecraft:dirt"
  },
  {
    "x": 14,
    "y": 2,
    "z": 11,
    "block": "minecraft:dirt"
  },
  {
    "x": 15,
    "y": 2,
    "z": 11,
    "block": "minecraft:dirt"
  },
  {
    "x": 16,
    "y": 2,
    "z": 11,
    "block": "minecraft:red_terracotta"
  },
  {
    "x": 0,
    "y": 2,
    "z": 12,
    "block": "minecraft:red_terracotta"
  },
  {
    "x": 1,
    "y": 2,
    "z": 12,
    "block": "minecraft:sand"
  },
  {
    "x": 2,
    "y": 2,
    "z": 12,
    "block": "minecraft:blue_stained_glass"
  },
  {
    "x": 3,
    "y": 2,
    "z": 12,
    "block": "minecraft:sand"
  },
  {
    "x": 4,
    "y": 2,
    "z": 12,
    "block": "minecraft:sand"
  },
  {
    "x": 5,
    "y": 2,
    "z": 12,
    "block": "minecraft:sand"
  },
  {
    "x": 6,
    "y": 2,
    "z": 12,
    "block": "minecraft:grass_block[snowy=false]"
  },
  {
    "x": 7,
    "y": 2,
    "z": 12,
    "block": "minecraft:grass_block[snowy=false]"
  },
  {
    "x": 8,
    "y": 2,
    "z": 12,
    "block": "minecraft:grass_block[snowy=false]"
  },
  {
    "x": 9,
    "y": 2,
    "z": 12,
    "block": "minecraft:dirt"
  },
  {
    "x": 10,
    "y": 2,
    "z": 12,
    "block": "minecraft:dirt"
  },
  {
    "x": 11,
    "y": 2,
    "z": 12,
    "block": "minecraft:dirt"
  },
  {
    "x": 12,
    "y": 2,
    "z": 12,
    "block": "minecraft:dirt"
  },
  {
    "x": 13,
    "y": 2,
    "z": 12,
    "block": "minecraft:dirt"
  },
  {
    "x": 14,
    "y": 2,
    "z": 12,
    "block": "minecraft:dirt"
  },
  {
    "x": 15,
    "y": 2,
    "z": 12,
    "block": "minecraft:dirt"
  },
  {
    "x": 16,
    "y": 2,
    "z": 12,
    "block": "minecraft:red_terracotta"
  },
  {
    "x": 0,
    "y": 2,
    "z": 13,
    "block": "minecraft:red_terracotta"
  },
  {
    "x": 1,
    "y": 2,
    "z": 13,
    "block": "minecraft:sand"
  },
  {
    "x": 2,
    "y": 2,
    "z": 13,
    "block": "minecraft:blue_stained_glass"
  },
  {
    "x": 3,
    "y": 2,
    "z": 13,
    "block": "minecraft:sand"
  },
  {
    "x": 4,
    "y": 2,
    "z": 13,
    "block": "minecraft:sand"
  },
  {
    "x": 5,
    "y": 2,
    "z": 13,
    "block": "minecraft:grass_block[snowy=false]"
  },
  {
    "x": 6,
    "y": 2,
    "z": 13,
    "block": "minecraft:grass_block[snowy=false]"
  },
  {
    "x": 7,
    "y": 2,
    "z": 13,
    "block": "minecraft:grass_block[snowy=false]"
  },
  {
    "x": 8,
    "y": 2,
    "z": 13,
    "block": "minecraft:dirt"
  },
  {
    "x": 9,
    "y": 2,
    "z": 13,
    "block": "minecraft:dirt"
  },
  {
    "x": 10,
    "y": 2,
    "z": 13,
    "block": "minecraft:dirt"
  },
  {
    "x": 11,
    "y": 2,
    "z": 13,
    "block": "minecraft:dirt"
  },
  {
    "x": 12,
    "y": 2,
    "z": 13,
    "block": "minecraft:dirt"
  },
  {
    "x": 13,
    "y": 2,
    "z": 13,
    "block": "minecraft:dirt"
  },
  {
    "x": 14,
    "y": 2,
    "z": 13,
    "block": "minecraft:dirt"
  },
  {
    "x": 15,
    "y": 2,
    "z": 13,
    "block": "minecraft:dirt"
  },
  {
    "x": 16,
    "y": 2,
    "z": 13,
    "block": "minecraft:red_terracotta"
  },
  {
    "x": 0,
    "y": 2,
    "z": 14,
    "block": "minecraft:red_terracotta"
  },
  {
    "x": 1,
    "y": 2,
    "z": 14,
    "block": "minecraft:sand"
  },
  {
    "x": 2,
    "y": 2,
    "z": 14,
    "block": "minecraft:blue_stained_glass"
  },
  {
    "x": 3,
    "y": 2,
    "z": 14,
    "block": "minecraft:blue_stained_glass"
  },
  {
    "x": 4,
    "y": 2,
    "z": 14,
    "block": "minecraft:sand"
  },
  {
    "x": 5,
    "y": 2,
    "z": 14,
    "block": "minecraft:sand"
  },
  {
    "x": 6,
    "y": 2,
    "z": 14,
    "block": "minecraft:grass_block[snowy=false]"
  },
  {
    "x": 7,
    "y": 2,
    "z": 14,
    "block": "minecraft:grass_block[snowy=false]"
  },
  {
    "x": 8,
    "y": 2,
    "z": 14,
    "block": "minecraft:dirt"
  },
  {
    "x": 9,
    "y": 2,
    "z": 14,
    "block": "minecraft:dirt"
  },
  {
    "x": 10,
    "y": 2,
    "z": 14,
    "block": "minecraft:dirt"
  },
  {
    "x": 11,
    "y": 2,
    "z": 14,
    "block": "minecraft:dirt"
  },
  {
    "x": 12,
    "y": 2,
    "z": 14,
    "block": "minecraft:dirt"
  },
  {
    "x": 13,
    "y": 2,
    "z": 14,
    "block": "minecraft:dirt"
  },
  {
    "x": 14,
    "y": 2,
    "z": 14,
    "block": "minecraft:dirt"
  },
  {
    "x": 15,
    "y": 2,
    "z": 14,
    "block": "minecraft:dirt"
  },
  {
    "x": 16,
    "y": 2,
    "z": 14,
    "block": "minecraft:red_terracotta"
  },
  {
    "x": 0,
    "y": 2,
    "z": 15,
    "block": "minecraft:red_terracotta"
  },
  {
    "x": 1,
    "y": 2,
    "z": 15,
    "block": "minecraft:sand"
  },
  {
    "x": 2,
    "y": 2,
    "z": 15,
    "block": "minecraft:sand"
  },
  {
    "x": 3,
    "y": 2,
    "z": 15,
    "block": "minecraft:blue_stained_glass"
  },
  {
    "x": 4,
    "y": 2,
    "z": 15,
    "block": "minecraft:blue_stained_glass"
  },
  {
    "x": 5,
    "y": 2,
    "z": 15,
    "block": "minecraft:sand"
  },
  {
    "x": 6,
    "y": 2,
    "z": 15,
    "block": "minecraft:grass_block[snowy=false]"
  },
  {
    "x": 7,
    "y": 2,
    "z": 15,
    "block": "minecraft:grass_block[snowy=false]"
  },
  {
    "x": 8,
    "y": 2,
    "z": 15,
    "block": "minecraft:grass_block[snowy=false]"
  },
  {
    "x": 9,
    "y": 2,
    "z": 15,
    "block": "minecraft:dirt"
  },
  {
    "x": 10,
    "y": 2,
    "z": 15,
    "block": "minecraft:dirt"
  },
  {
    "x": 11,
    "y": 2,
    "z": 15,
    "block": "minecraft:dirt"
  },
  {
    "x": 12,
    "y": 2,
    "z": 15,
    "block": "minecraft:dirt"
  },
  {
    "x": 13,
    "y": 2,
    "z": 15,
    "block": "minecraft:dirt"
  },
  {
    "x": 14,
    "y": 2,
    "z": 15,
    "block": "minecraft:dirt"
  },
  {
    "x": 15,
    "y": 2,
    "z": 15,
    "block": "minecraft:dirt"
  },
  {
    "x": 16,
    "y": 2,
    "z": 15,
    "block": "minecraft:red_terracotta"
  },
  {
    "x": 0,
    "y": 2,
    "z": 16,
    "block": "minecraft:white_terracotta"
  },
  {
    "x": 1,
    "y": 2,
    "z": 16,
    "block": "minecraft:grass_block[snowy=false]"
  },
  {
    "x": 2,
    "y": 2,
    "z": 16,
    "block": "minecraft:sand"
  },
  {
    "x": 3,
    "y": 2,
    "z": 16,
    "block": "minecraft:blue_stained_glass"
  },
  {
    "x": 4,
    "y": 2,
    "z": 16,
    "block": "minecraft:blue_stained_glass"
  },
  {
    "x": 5,
    "y": 2,
    "z": 16,
    "block": "minecraft:sand"
  },
  {
    "x": 6,
    "y": 2,
    "z": 16,
    "block": "minecraft:sand"
  },
  {
    "x": 7,
    "y": 2,
    "z": 16,
    "block": "minecraft:grass_block[snowy=false]"
  },
  {
    "x": 8,
    "y": 2,
    "z": 16,
    "block": "minecraft:grass_block[snowy=false]"
  },
  {
    "x": 9,
    "y": 2,
    "z": 16,
    "block": "minecraft:dirt"
  },
  {
    "x": 10,
    "y": 2,
    "z": 16,
    "block": "minecraft:dirt"
  },
  {
    "x": 11,
    "y": 2,
    "z": 16,
    "block": "minecraft:dirt"
  },
  {
    "x": 12,
    "y": 2,
    "z": 16,
    "block": "minecraft:dirt"
  },
  {
    "x": 13,
    "y": 2,
    "z": 16,
    "block": "minecraft:dirt"
  },
  {
    "x": 14,
    "y": 2,
    "z": 16,
    "block": "minecraft:dirt"
  },
  {
    "x": 15,
    "y": 2,
    "z": 16,
    "block": "minecraft:dirt"
  },
  {
    "x": 16,
    "y": 2,
    "z": 16,
    "block": "minecraft:white_terracotta"
  },
  {
    "x": 0,
    "y": 2,
    "z": 17,
    "block": "minecraft:blue_terracotta"
  },
  {
    "x": 1,
    "y": 2,
    "z": 17,
    "block": "minecraft:grass_block[snowy=false]"
  },
  {
    "x": 2,
    "y": 2,
    "z": 17,
    "block": "minecraft:sand"
  },
  {
    "x": 3,
    "y": 2,
    "z": 17,
    "block": "minecraft:packed_mud"
  },
  {
    "x": 4,
    "y": 2,
    "z": 17,
    "block": "minecraft:blue_stained_glass"
  },
  {
    "x": 5,
    "y": 2,
    "z": 17,
    "block": "minecraft:blue_stained_glass"
  },
  {
    "x": 6,
    "y": 2,
    "z": 17,
    "block": "minecraft:sand"
  },
  {
    "x": 7,
    "y": 2,
    "z": 17,
    "block": "minecraft:grass_block[snowy=false]"
  },
  {
    "x": 8,
    "y": 2,
    "z": 17,
    "block": "minecraft:grass_block[snowy=false]"
  },
  {
    "x": 9,
    "y": 2,
    "z": 17,
    "block": "minecraft:grass_block[snowy=false]"
  },
  {
    "x": 10,
    "y": 2,
    "z": 17,
    "block": "minecraft:dirt"
  },
  {
    "x": 11,
    "y": 2,
    "z": 17,
    "block": "minecraft:dirt"
  },
  {
    "x": 12,
    "y": 2,
    "z": 17,
    "block": "minecraft:dirt"
  },
  {
    "x": 13,
    "y": 2,
    "z": 17,
    "block": "minecraft:dirt"
  },
  {
    "x": 14,
    "y": 2,
    "z": 17,
    "block": "minecraft:dirt"
  },
  {
    "x": 15,
    "y": 2,
    "z": 17,
    "block": "minecraft:dirt"
  },
  {
    "x": 16,
    "y": 2,
    "z": 17,
    "block": "minecraft:blue_terracotta"
  },
  {
    "x": 0,
    "y": 2,
    "z": 18,
    "block": "minecraft:blue_terracotta"
  },
  {
    "x": 1,
    "y": 2,
    "z": 18,
    "block": "minecraft:grass_block[snowy=false]"
  },
  {
    "x": 2,
    "y": 2,
    "z": 18,
    "block": "minecraft:sand"
  },
  {
    "x": 3,
    "y": 2,
    "z": 18,
    "block": "minecraft:packed_mud"
  },
  {
    "x": 4,
    "y": 2,
    "z": 18,
    "block": "minecraft:blue_stained_glass"
  },
  {
    "x": 5,
    "y": 2,
    "z": 18,
    "block": "minecraft:blue_stained_glass"
  },
  {
    "x": 6,
    "y": 2,
    "z": 18,
    "block": "minecraft:packed_mud"
  },
  {
    "x": 7,
    "y": 2,
    "z": 18,
    "block": "minecraft:grass_block[snowy=false]"
  },
  {
    "x": 8,
    "y": 2,
    "z": 18,
    "block": "minecraft:grass_block[snowy=false]"
  },
  {
    "x": 9,
    "y": 2,
    "z": 18,
    "block": "minecraft:grass_block[snowy=false]"
  },
  {
    "x": 10,
    "y": 2,
    "z": 18,
    "block": "minecraft:dirt"
  },
  {
    "x": 11,
    "y": 2,
    "z": 18,
    "block": "minecraft:dirt"
  },
  {
    "x": 12,
    "y": 2,
    "z": 18,
    "block": "minecraft:dirt"
  },
  {
    "x": 13,
    "y": 2,
    "z": 18,
    "block": "minecraft:dirt"
  },
  {
    "x": 14,
    "y": 2,
    "z": 18,
    "block": "minecraft:dirt"
  },
  {
    "x": 15,
    "y": 2,
    "z": 18,
    "block": "minecraft:dirt"
  },
  {
    "x": 16,
    "y": 2,
    "z": 18,
    "block": "minecraft:blue_terracotta"
  },
  {
    "x": 0,
    "y": 2,
    "z": 19,
    "block": "minecraft:blue_terracotta"
  },
  {
    "x": 1,
    "y": 2,
    "z": 19,
    "block": "minecraft:grass_block[snowy=false]"
  },
  {
    "x": 2,
    "y": 2,
    "z": 19,
    "block": "minecraft:sand"
  },
  {
    "x": 3,
    "y": 2,
    "z": 19,
    "block": "minecraft:sand"
  },
  {
    "x": 4,
    "y": 2,
    "z": 19,
    "block": "minecraft:blue_stained_glass"
  },
  {
    "x": 5,
    "y": 2,
    "z": 19,
    "block": "minecraft:blue_stained_glass"
  },
  {
    "x": 6,
    "y": 2,
    "z": 19,
    "block": "minecraft:sand"
  },
  {
    "x": 7,
    "y": 2,
    "z": 19,
    "block": "minecraft:sand"
  },
  {
    "x": 8,
    "y": 2,
    "z": 19,
    "block": "minecraft:grass_block[snowy=false]"
  },
  {
    "x": 9,
    "y": 2,
    "z": 19,
    "block": "minecraft:grass_block[snowy=false]"
  },
  {
    "x": 10,
    "y": 2,
    "z": 19,
    "block": "minecraft:dirt"
  },
  {
    "x": 11,
    "y": 2,
    "z": 19,
